Workbook

Sheet 00_START_HERE
B2: HỆ THỐNG TRACKING TĂNG CÂN & TĂNG CƠ CÁ NHÂN HÓA (BULKING SYSTEM 2026)
B3: Thiết kế tích hợp: S&C Coach • Chuyên gia Dinh dưỡng Thể thao • Kỹ sư Excel & Phân tích Dữ liệu
B5: ⚠️ CẢNH BÁO SỨC KHỎE QUAN TRỌNG (HEALTH & MEDICAL DISCLAIMER): Chỉ số BMI baseline ngày 19/10/2026 là 16.4 (Chiều cao 175cm, Cân nặng 50.3kg) thuộc phân loại THIẾU CÂN ĐÁNG LƯU Ý đối với nam giới trưởng thành. Tỷ lệ mỡ PBF 7.8% là mức rất thấp. Workbook này là công cụ tự theo dõi thói quen dinh dưỡng và tập luyện cá nhân hóa, KHÔNG THAY THẾ CHẨN ĐOÁN HOẶC CHỈ ĐỊNH Y KHOA. Khuyến nghị bạn đi khám tổng quát và tham khảo ý kiến Bác sĩ/Chuyên gia Dinh dưỡng lâm sàng, đặc biệt nếu tình trạng thiếu cân kéo dài, có sút cân không chủ ý hoặc có triệu chứng tiêu hóa/mệt mỏi bất thường.
B8: 1. CHÚ GIẢI MÀU SẮC & QUY TẮC NHẬP LIỆU (COLOR LEGEND & INPUT CONVENTIONS)
B9: Loại Ô / Quy Ước | C9: Mẫu Trực Quan & Ý Nghĩa | D9: Hành Động Của Bạn | E9: Ghi Chú Kỹ Thuật
B10: Ô Nhập Liệu Người Dùng (User Input) | C10: Màu Xanh Nhạt viền Xanh | D10: Người dùng tự nhập tay hoặc chọn từ Dropdown. | E10: Tương thích Microsoft Excel macOS & Windows
B11: Ô Công Thức Tự Động (Automated Formula) | C11: Màu Xám Nhẹ Neutral | D11: Tuyệt đối không sửa! Công thức tự tính toán. | E11: Tương thích Microsoft Excel macOS & Windows
B12: Cột Mốc / Đạt Chỉ Tiêu (Target Hit / Success) | C12: Màu Xanh Lá (Emerald) | D12: Đã hoàn thành mục tiêu hoặc tuân thủ tốt. | E12: Tương thích Microsoft Excel macOS & Windows
B13: Cảnh Báo / Cần Cấu Hình (Warning / Pending) | C13: Màu Vàng Hổ Phách (Amber) | D13: Thông tin chưa cấu hình hoặc số liệu thiếu. | E13: Tương thích Microsoft Excel macOS & Windows
B14: Dữ Liệu Mẫu Tham Khảo (Sample Data) | C14: Màu Tím Nhạt (Purple) | D14: Dữ liệu mẫu minh họa [SAMPLE], không tính vào kết quả thật. | E14: Tương thích Microsoft Excel macOS & Windows
B16: 2. QUY TRÌNH VẬN HÀNH CHUẨN (DAILY - WEEKLY - MONTHLY WORKFLOW)
B17: Tần Suất | C17: Bước Thực Hiện | D17: Hướng Dẫn Chi Tiết Chuyên Gia | E17: Worksheet Trọng Tâm
B18: MỖI NGÀY (Hằng sáng) | C18: 1. Cân sáng | D18: Cân ngay sau khi thức dậy và đi vệ sinh, trước khi ăn uống. Nhập vào Sheet 10. | E18: Sheet 10_BODY_WEIGHT_LOG
B19: MỖI NGÀY (Trong ngày) | C19: 2. Ghi nhận món ăn | D19: Ghi lại từng món ăn và khối lượng (g/ml). Chọn mức tin cậy (Đã cân / Ước lượng). | E19: Sheet 06_DAILY_NUTRITION_LOG
B20: MỖI NGÀY (Buổi tập) | C20: 3. Ghi chép tạ & reps | D20: Mở nhật ký tập luyện, ghi mức tạ thực tế, số reps đạt được và RIR từng hiệp. | E20: Sheet 09_WORKOUT_LOG
B21: MỖI NGÀY (Cuối ngày) | C21: 4. Kiểm tra chỉ tiêu | D21: Xem tổng calo/protein trong ngày. Đảm bảo trạng thái ngày chuyển thành COMPLETE. | E21: Sheet 06 & 13_DASHBOARD
B22: HẰNG TUẦN (Chủ nhật) | C22: 5. Review & Điều chỉnh | D22: Đánh giá cân nặng TB 7 ngày, tỷ lệ tuân thủ calo, số buổi tập hoàn thành. | E22: Sheet 12_WEEKLY_REVIEW
B23: HẰNG THÁNG (4-8 tuần) | C23: 6. Kiểm tra InBody | D23: Đo lại InBody trong cùng điều kiện. Đánh giá tốc độ tăng cơ SMM vs tăng mỡ. | E23: Sheet 11_INBODY_HISTORY
B25: 3. DANH MỤC WORKSHEETS & CHỨC NĂNG HỆ THỐNG (SYSTEM DIRECTORY)
B26: Tên Sheet | C26: Tên Tiếng Việt | D26: Chức Năng & Mục Đích | E26: Trạng Thái Sử Dụng
B27: 00_START_HERE | C27: Bắt đầu tại đây | D27: Hướng dẫn sử dụng, checklist khởi tạo, quy trình SOP & cảnh báo y tế. | E27: Bắt buộc đọc trước khi dùng
B28: 01_PROFILE_GOALS | C28: Hồ sơ & Mục tiêu | D28: Quản lý dữ liệu nhân trắc, baseline 19/10/2026, các cột mốc 55-60-65kg & thói quen sinh hoạt. | E28: Bổ sung thông tin còn thiếu
B29: 02_NUTRITION_SETUP | C29: Thiết lập Dinh dưỡng | D29: Phân tích BMR, TDEE, lộ trình calo thặng dư an toàn & chia tỷ lệ Macronutrients. | E29: Đang ở mức Thử nghiệm
B30: 03_FOOD_DATABASE | C30: Cơ sở Thực phẩm | D30: Database 40+ thực phẩm Việt Nam, phân định sống/chín, calo, protein, carb, fat, giá tiền. | E30: Tra cứu & bổ sung món mới
B31: 04_RECIPE_DATABASE | C31: Công thức Món ăn | D31: Quản lý công thức sinh tố tăng cân, bữa ăn sinh viên, tính tự động macro từ Food DB. | E31: Mẫu tham khảo [SAMPLE]
B32: 05_WEEKLY_MEAL_PLAN | C32: Kế hoạch Thực đơn | D32: Lịch ăn mẫu 7 ngày tối ưu chi phí & thời gian chuẩn bị bữa cho sinh viên. | E32: Kế hoạch tuần
B33: 06_DAILY_NUTRITION_LOG | C33: Nhật ký Ăn uống | D33: Nhập thực tế những gì đã ăn mỗi ngày. Tự động tính calo, protein. Không tính ngày trống là 0 calo. | E33: Nhập hằng ngày
B34: 07_WORKOUT_EXERCISE_DB | C34: Danh mục Bài tập | D34: 35 bài tập chuẩn Hypertrophy phân nhóm cơ, dụng cụ, kỹ thuật, an toàn & bài thay thế. | E34: Tra cứu kỹ thuật
B35: 08_WEEKLY_WORKOUT_PLAN | C35: Giáo án Tập luyện | D35: Lịch tập 4 buổi Upper/Lower tối ưu phục hồi cho thể trạng 50.3kg, nguyên tắc tăng tải. | E35: Kế hoạch tập
B36: 09_WORKOUT_LOG | C36: Nhật ký Tập luyện | D36: Ghi chép chi tiết từng hiệp tập: mức tạ, reps, RIR/RPE, phát hiện chững tạ & đau bất thường. | E36: Nhập sau mỗi buổi tập
B37: 10_BODY_WEIGHT_LOG | C37: Theo dõi Cân nặng | D37: Ghi cân nặng sáng 24 tuần, vòng eo, trung bình 7 ngày, khoảng cách tới mốc 55-60-65kg. | E37: Nhập mỗi sáng
... B41: 14_SETTINGS_VALIDATION | C41: Danh mục & Cấu hình | D41: Chứa toàn bộ danh sách dropdown cho workbook: Bữa ăn, Nhóm cơ, Trạng thái, Thang đo. | E41: Cấu hình hệ thống
B44: 4. CHECKLIST KHỞI TẠO HỒ SƠ BAN ĐẦU (PROFILE INITIALIZATION CHECKLIST)
B45: Hạng Mục Kiểm Tra | C45: Nội Dung Chi Tiết | D45: Trạng Thái Hiện Tại | E45: Hành Động Tiếp Theo
B46: Số liệu InBody Baseline (19/10/2026) | C46: Chiều cao 175cm, Cân nặng 50.3kg, SMM 25.7kg, PBF 7.8% | D46: ĐÃ XÁC NHẬN | E46: Đã tích hợp sẵn vào Sheet 01 & 11
B47: Xác nhận số ngày tập gym khả thi | C47: Số buổi có thể tập đều đặn mỗi tuần (Khuyến nghị 3-4 buổi) | D47: CHƯA CẤU HÌNH | E47: Vào Sheet 01 để bổ sung
B48: Xác nhận kinh nghiệm & kỹ thuật tập | C48: Đã tập bao lâu, khả năng thực hiện Bench Press, Squat, Lat Pulldown | D48: CHƯA CẤU HÌNH | E48: Vào Sheet 01 để bổ sung
B49: Xác nhận mức độ vận động ngoài gym (NEAT) | C49: Đi học, ngồi nhiều, đi bộ, làm việc chân tay... | D49: CHƯA CẤU HÌNH | E49: Vào Sheet 01 để bổ sung
B50: Xác nhận thời gian ngủ trung bình | C50: Số giờ ngủ hằng đêm (Quan trọng sống còn cho tăng cơ) | D50: CHƯA CẤU HÌNH | E50: Vào Sheet 01 để bổ sung
B51: Xác nhận ngân sách & thói quen ăn uống | C51: Ngân sách/ngày, khả năng nấu nướng, dị ứng lactose... | D51: CHƯA CẤU HÌNH | E51: Vào Sheet 01 để bổ sung
...

Sheet 01_PROFILE_GOALS
B2: HỒ SƠ CÁ NHÂN & LỘ TRÌNH MỤC TIÊU (PROFILE & GOALS)
B4: 1. THÔNG TIN NHÂN TRẮC & CHỈ SỐ INBODY BAN ĐẦU (19/10/2026)
B5: Chỉ Số / Thông Tin | C5: Giá Trị | D5: Trạng Thái | E5: Ghi Chú Chuyên Môn
B6: Giới tính | C6: Nam | D6: ĐÃ XÁC NHẬN | E6: Đọc từ phiếu InBody
B7: Tuổi | C7: 21 | D7: ĐÃ XÁC NHẬN | E7: 21 tuổi
B8: Chiều cao (Height) | C8: 175 | D8: ĐÃ XÁC NHẬN | E8: cm (Đo tại phòng tập)
B9: Cân nặng Baseline (Weight) | C9: 50.3 | D9: ĐÃ XÁC NHẬN | E9: kg (Thời điểm đo 19/10/2026)
B10: Chỉ số BMI Baseline | C10: =C9/((C8/100)^2) | D10: TỰ ĐỘNG TÍNH | E10: kg/m² (Mức 16.4: Thiếu cân đáng lưu ý)
B11: Khối lượng cơ xương (SMM) | C11: 25.7 | D11: ĐÃ XÁC NHẬN | E11: kg (Mục tiêu tăng lên >30 kg)
B12: Khối lượng mỡ (Body Fat Mass) | C12: 3.9 | D12: ĐÃ XÁC NHẬN | E12: kg (Rất thấp)
B13: Tỷ lệ mỡ cơ thể (PBF) | C13: 0.078 | D13: ĐÃ XÁC NHẬN | E13: % (Số đo máy 7.8%)
B14: Tỷ lệ trao đổi chất cơ bản (BMR) | C14: 1371 | D14: ĐÃ XÁC NHẬN | E14: kcal/ngày (Năng lượng duy trì sự sống cơ bản)
B15: Năng lượng InBody khuyến nghị | C15: 2648 | D15: MỐC THAM KHẢO | E15: kcal/ngày (Cần kiểm chứng bằng thực tế)
B16: Ngày bắt đầu tracking | C16: 46314 | D16: ĐÃ XÁC NHẬN | E16: Bắt đầu chu kỳ 24 tuần
B18: 2. THÓI QUEN SINH HOẠT, VẬN ĐỘNG & NGÂN SÁCH (CẦN NGƯỜI DÙNG BỔ SUNG)
B19: Trường Thông Tin | C19: Giá Trị Thiết Lập (Ô Nhập Liệu) | D19: Trạng Thái | E19: Hướng Dẫn / Lưu Ý Chuyên Gia
B20: Số ngày tập gym mục tiêu mỗi tuần | C20: 4 | D20: CHƯA CẤU HÌNH | E20: buổi/tuần (Khuyến nghị 4 buổi: Upper/Lower)
B21: Kinh nghiệm tập luyện thể hình | C21: Dưới 6 tháng / Đang làm quen | D21: CHƯA CẤU HÌNH | E21: Cần xác nhận kỹ thuật các bài cơ bản
B22: Mức độ vận động ngoài gym (NEAT) | C22: Ngồi nhiều (Sinh viên / Văn phòng) | D22: CHƯA CẤU HÌNH | E22: Ảnh hưởng lớn đến mức tiêu hao TDEE
B23: Thời gian ngủ trung bình mỗi đêm | C23: 7 | D23: CHƯA CẤU HÌNH | E23: giờ/đêm (Tối thiểu 7-8h để cơ bắp phục hồi)
B24: Ngân sách ăn uống ước tính | C24: 90000 | D24: CHƯA CẤU HÌNH | E24: VNĐ/ngày (~2.700.000 VNĐ/tháng)
B25: Số bữa ăn có thể duy trì mỗi ngày | C25: 4 bữa (3 chính + 1 phụ) | D25: CHƯA CẤU HÌNH | E25: Chia nhỏ bữa giúp giảm áp lực dạ dày
B26: Khẩu vị & Thực phẩm thường ăn | C26: Cơm trắng, trứng, ức gà, thịt heo, chuối | D26: CHƯA CẤU HÌNH | E26: Ưu tiên thực phẩm dễ mua, giá rẻ
B27: Dị ứng hoặc không dung nạp thức ăn | C27: Không có / Đang theo dõi lactose | D27: CHƯA CẤU HÌNH | E27: Lưu ý nếu uống sữa bò bị đầy bụng
B28: Trang thiết bị tập luyện sẵn có | C28: Phòng gym thương mại đầy đủ máy & tạ | D28: CHƯA CẤU HÌNH | E28: Đủ Barbell, Dumbbell, Cáp và Máy
B29: Hạn chế chấn thương / Đau mỏi khớp | C29: Không có chấn thương lưng/khớp | D29: CHƯA CẤU HÌNH | E29: Nếu đau khớp cần đổi bài tập ngay
B30: 3. LỘ TRÌNH CÁC CỘT MỐC CÂN NẶNG & TIẾN TRÌNH THỰC TẾ (WEIGHT MILESTONES)
B31: Chỉ Tiêu / Cột Mốc | C31: Mục Tiêu / Thực Tế | D31: Chênh Lệch / Đơn Vị | E31: Ý Nghĩa Giai Đoạn & Phân Tích
B32: Baseline (19/10/2026) | C32: 50.3 | D32: Mốc xuất phát | E32: BMI 16.4 - Điểm khởi đầu của hành trình
B33: Cột mốc 1 (Milestone 1) | C33: 55 | D33: +4.7 kg | E33: Thích nghi ăn thặng dư calo, tăng sức mạnh cơ bản
B34: Cột mốc 2 (Milestone 2) | C34: 60 | D34: +9.7 kg | E34: Thoát khỏi ngưỡng BMI thiếu cân (BMI đạt ~19.6)
B35: Cột mốc 3 (Milestone 3 - Mục tiêu dài hạn) | C35: 65 | D35: +14.7 kg | E35: Thể hình cân đối, cơ bắp săn chắc (BMI ~21.2)
B36: Cân nặng mục tiêu trên InBody | C36: 67.4 | D36: +17.1 kg | E36: Mốc tham khảo tối đa từ thuật toán InBody
B37: --- TIẾN ĐỘ THỜI GIAN THỰC --- | E37: CÔNG THỨC TỰ ĐỘNG TÍNH TOÁN
B38: Cân nặng hiện tại (Mới nhất) | C38: =LOOKUP(9.99E+307, '10_BODY_WEIGHT_LOG'!$C$4:$C$171) | D38: kg | E38: Tự động liên kết từ Sheet 10
B39: Tổng số kg đã tăng so với baseline | C39: =MAX(0, C38-50.3) | D39: kg | E39: Tiến triển thực tế
B40: Khoảng cách còn lại đến Cột mốc 55 kg | C40: =MAX(0, 55-C38) | D40: kg | E40: Khoảng cách mốc 1
B41: Khoảng cách còn lại đến Cột mốc 60 kg | C41: =MAX(0, 60-C38) | D41: kg | E41: Khoảng cách mốc 2
B42: Khoảng cách còn lại đến Mục tiêu 65 kg | C42: =MAX(0, 65-C38) | D42: kg | E42: Khoảng cách mục tiêu dài hạn
B43: Tỷ lệ hoàn thành mục tiêu 65 kg | C43: =IF(C38<=50.3, 0, (C38-50.3)/(65-50.3)) | D43: % | E43: Phần trăm chặng đường
...

Sheet 02_NUTRITION_SETUP
B2: THIẾT LẬP MỤC TIÊU DINH DƯỠNG & NĂNG LƯỢNG (NUTRITION SETUP)
B4: 1. CƠ SỞ CHUYỂN HÓA & PHÂN TÍCH TỪ CHUYÊN GIA DINH DƯỠNG
B5: Thông Số Chuyển Hóa | C5: Giá Trị | D5: Phân Loại | E5: Phân Tích Chuyên Môn
B6: BMR từ máy InBody (19/10/2026) | C6: 1371 | D6: kcal/ngày | E6: Năng lượng cơ bản ở trạng thái nghỉ hoàn toàn
B7: BMR theo công thức Katch-McArdle | C7: =370+(21.6*'11_INBODY_HISTORY'!K4) | D7: kcal/ngày | E7: Tính từ FFM 46.4kg (Trùng khớp 1.372 kcal)
B8: Calo InBody khuyến nghị trên phiếu | C8: 2648 | D8: MỐC THAM KHẢO | E8: Thuật toán máy ước tính (CHƯA PHẢI MỤC TIÊU NGAY)
B9: Khuyến nghị của Chuyên gia Dinh dưỡng | C9: Bắt đầu với 2.100 kcal | D9: CHIẾN LƯỢC | E9: Không nhảy ngay lên 2.648 kcal để tránh quá tải dạ dày
B11: 2. BẢNG ƯỚC TÍNH TỔNG TIÊU HAO NĂNG LƯỢNG HẰNG NGÀY (TDEE TABLE)
B12: Mức Độ Hoạt Động (PAL) | C12: TDEE Ước Tính | D12: Hệ Số Nhân (Multiplier) | E12: Ghi Chú Đánh Giá Thể Trạng
B13: Ít vận động (Sedentary - Ngồi học nhiều) | C13: =C6*1.2 | D13: Hệ số PAL: 1.20 | E13: Duy trì không tập: ~1.645 kcal
B14: Vận động nhẹ (Light - Tập 1-3 buổi/tuần) | C14: =C6*1.375 | D14: Hệ số PAL: 1.375 | E14: Duy trì tập nhẹ: ~1.885 kcal
B15: Vận động vừa (Moderate - Tập 3-4 buổi/tuần) | C15: =C6*1.55 | D15: Hệ số PAL: 1.55 | E15: Mức ước tính phù hợp: ~2.125 kcal
B16: Vận động nặng (Very Active - Tập nặng 5+ buổi) | C16: =C6*1.725 | D16: Hệ số PAL: 1.725 | E16: Mức tiêu hao cao: ~2.365 kcal
B18: 3. THIẾT LẬP MỤC TIÊU MACRONUTRIENTS CHÍNH THỨC (OFFICIAL TARGETS)
B19: Chỉ Tiêu Dinh Dưỡng | C19: Giá Trị Mục Tiêu | D19: Trạng Thái Cấu Hình | E19: Cơ Sở Khoa Học & Phân Bổ Năng Lượng
B20: Mục tiêu Năng lượng hằng ngày (Daily Kcal Target) | C20: 2100 | D20: Đang thử nghiệm | E20: Thặng dư an toàn giai đoạn 1 (+250 kcal trên TDEE duy trì)
B21: Mục tiêu Protein hằng ngày | C21: 100 | D21: Đang thử nghiệm | E21: ~2.0 g/kg thể trọng (400 kcal = 19.0% tổng calo)
B22: Mục tiêu Chất béo (Fat) hằng ngày | C22: 55 | D22: Đang thử nghiệm | E22: ~1.1 g/kg thể trọng (495 kcal = 23.6% tổng calo)
B23: Mục tiêu Carbohydrate (Carb) hằng ngày | C23: 300 | D23: Đang thử nghiệm | E23: Nguồn năng lượng chính (1.200 kcal = 57.1% tổng calo)
B24: Tổng Calo tính lại từ Macros (Kiểm tra) | C24: =(C21*4)+(C22*9)+(C23*4) | D24: TỰ ĐỘNG KHỚP | E24: Công thức: (Protein*4) + (Fat*9) + (Carb*4)
B25: Mục tiêu Nước uống hằng ngày | C25: 2500 | D25: Đang thử nghiệm | E25: ml/ngày (Đảm bảo bù dịch khi tập và tiêu hóa carb)
B26: Số bữa ăn mục tiêu mỗi ngày | C26: 4 | D26: Đang thử nghiệm | E26: bữa (3 bữa chính + 1 bữa phụ dinh dưỡng cao)

Sheet 03_FOOD_DATABASE
A1: CƠ SỞ DỮ LIỆU THỰC PHẨM VIỆT NAM CHO SINH VIÊN (FOOD DATABASE)
A2: LƯU Ý QUAN TRỌNG: Phân định rạch ròi Thực phẩm SỐNG (Raw) và NẤU CHÍN (Cooked). 100g gạo khô nở ra ~230g cơm trắng; 100g thịt sống ngót lại ~75-80g khi chín!
A4: Food ID | B4: Tên Thực Phẩm | C4: Nhóm Thực Phẩm | D4: Trạng Thái | E4: Đơn Vị | F4: Khẩu Phần | G4: Kcal / 100g | H4: Protein (g) | I4: Carb (g) | J4: Fat (g) | K4: Fiber (g) | L4: Giá Tham Khảo | M4: Nguồn Dữ Liệu | N4: Ghi Chú Chuyên Môn
A5: FD001 | B5: Cơm trắng (nấu chín) | C5: Tinh bột | D5: Nấu chín | E5: g | F5: 150 | G5: 130 | H5: 2.7 | I5: 28.2 | J5: 0.3 | K5: 0.4 | L5: 2500 | M5: Viện Dinh Dưỡng QG | N5: 100g gạo khô nở ra ~230g cơm trắng
A6: FD002 | B6: Gạo tẻ trắng (hạt khô) | C6: Tinh bột | D6: Khô | E6: g | F6: 100 | G6: 344 | H6: 7.6 | I6: 76.2 | J6: 0.7 | K6: 1.3 | L6: 2000 | M6: Viện Dinh Dưỡng QG | N6: Dùng khi cân gạo trước khi cắm cơm
A7: FD003 | B7: Yến mạch cán dẹt (Rolled Oats) | C7: Tinh bột | D7: Khô | E7: g | F7: 50 | G7: 389 | H7: 16.9 | I7: 66.3 | J7: 6.9 | K7: 10.6 | L7: 7000 | M7: USDA Nutrient Database | N7: Tuyệt vời để xay sinh tố tăng cân
A8: FD004 | B8: Khoai lang luộc | C8: Tinh bột | D8: Nấu chín | E8: g | F8: 150 | G8: 86 | H8: 1.6 | I8: 20.1 | J8: 0.1 | K8: 3 | L8: 3000 | M8: Viện Dinh Dưỡng QG | N8: Carb hấp thu chậm, nhiều khoáng chất
A9: FD005 | B9: Bánh mì sandwich trắng | C9: Tinh bột | D9: Đóng gói / Chế biến | E9: g | F9: 60 | G9: 265 | H9: 8.9 | I9: 49.1 | J9: 3.2 | K9: 2.7 | L9: 4000 | M9: Bao bì Kinh Đô / Staff | N9: 1 lát chuẩn ~25-30g
A10: FD006 | B10: Bánh mì ổ Việt Nam | C10: Tinh bột | D10: Đóng gói / Chế biến | E10: ổ | F10: 80 | G10: 250 | H10: 8 | I10: 52 | J10: 1.5 | K10: 2 | L10: 5000 | M10: Ước tính tiêu chuẩn | N10: 1 ổ bánh mì không ruột vừa ~80g
A11: FD007 | B11: Chuối tiêu chín | C11: Tinh bột | D11: Sống / Tươi | E11: g | F11: 100 | G11: 89 | H11: 1.1 | I11: 22.8 | J11: 0.3 | K11: 2.6 | L11: 2000 | M11: Viện Dinh Dưỡng QG | N11: 1 quả chuối vừa bỏ vỏ ~90-100g
A12: FD008 | B12: Phở tươi / Bánh phở | C12: Tinh bột | D12: Nấu chín | E12: g | F12: 150 | G12: 120 | H12: 2 | I12: 28 | J12: 0.2 | K12: 0.5 | L12: 3000 | M12: Viện Dinh Dưỡng QG | N12: Bánh phở trần nước sôi
A13: FD009 | B13: Bún tươi | C13: Tinh bột | D13: Nấu chín | E13: g | F13: 150 | G13: 110 | H13: 1.7 | I13: 25.7 | J13: 0 | K13: 0.5 | L13: 2500 | M13: Viện Dinh Dưỡng QG | N13: Hàm lượng nước cao, dễ nuốt
A14: FD010 | B14: Ngô ngọt (Bắp Mỹ luộc) | C14: Tinh bột | D14: Nấu chín | E14: g | F14: 100 | G14: 96 | H14: 3.4 | I14: 21 | J14: 1.5 | K14: 2.4 | L14: 4000 | M14: USDA Nutrient Database | N14: Vị ngọt tự nhiên, dễ ăn bữa phụ
A15: FD011 | B15: Ức gà sống (bỏ da) | C15: Nguồn đạm | D15: Sống / Tươi | E15: g | F15: 150 | G15: 120 | H15: 22.5 | I15: 0 | J15: 2.6 | K15: 0 | L15: 8000 | M15: Viện Dinh Dưỡng QG | N15: Cân khi sống, đạm tinh khiết giá rẻ
A16: FD012 | B16: Ức gà áp chảo / Luộc | C16: Nguồn đạm | D16: Nấu chín | E16: g | F16: 100 | G16: 165 | H16: 31 | I16: 0 | J16: 3.6 | K16: 0 | L16: 10500 | M16: USDA / Phép đo ngót | N16: Ngót nước ~25%, đạm đậm đặc hơn
... A46: FD042 | B46: Nước lọc tinh khiết | C46: Gia vị & Khác | D46: Đóng gói / Chế biến | E46: ml | F46: 500 | G46: 0 | H46: 0 | I46: 0 | J46: 0 | K46: 0 | L46: 1000 | M46: Quy chuẩn | N46: Uống đủ 2.5 lít/ngày

Sheet 04_RECIPE_DATABASE
A1: CÔNG THỨC MÓN ĂN TĂNG CÂN & MEAL-PREP CHO SINH VIÊN (RECIPE DATABASE)
A2: Các món mẫu [SAMPLE] được tính toán từ Food Database. Bạn có thể thêm các món gia đình thường nấu để nhập liệu nhanh hơn!
A4: Recipe ID | B4: Tên Món Ăn | C4: Danh Sách Nguyên Liệu Chi Tiết | D4: Tổng Kcal | E4: Protein (g) | F4: Carb (g) | G4: Fat (g) | H4: Khẩu Phần | I4: Kcal / Suất | J4: P / Suất | K4: C / Suất | L4: F / Suất | M4: Giá / Suất | N4: Thời Gian | O4: Hướng Dẫn Nấu & Bảo Quản
A5: RCP001 | B5: [SAMPLE] Sinh Tố Mass Tự Làm (Home-made Shake) | C5: 1 quả chuối (100g) + 220ml Sữa tươi + 40g Yến mạch + 30g Bơ đậu phộng + 15g Sữa đặc | D5: 625 | E5: 20.5 | F5: 81 | G5: 24 | H5: 1 | I5: =D5/H5 | J5: =E5/H5 | K5: =F5/H5 | L5: =G5/H5 | M5: 19000 | N5: 5 phút | O5: Cho tất cả vào máy xay sinh tố 60s. Uống bữa phụ chiều hoặc sau tập. Rất dễ nuốt!
A6: RCP002 | B6: [SAMPLE] Cơm Ức Gà Xào Nấm & Trứng Ốp La | C6: 250g Cơm trắng chín + 150g Ức gà sống xào + 1 quả Trứng gà + 5g Dầu ăn + Rau cải | D6: 680 | E6: 48 | F6: 76 | G6: 19 | H6: 1 | I6: =D6/H6 | J6: =E6/H6 | K6: =F6/H6 | L6: =G6/H6 | M6: 32000 | N6: 20 phút | O6: Xào ức gà với nấm và dầu ăn, ốp la trứng lòng đào ăn kèm cơm nóng. Chia hộp mang theo.
A7: RCP003 | B7: [SAMPLE] Bánh Mì Kẹp Trứng & Bơ Đậu Phộng | C7: 2 lát sandwich (60g) + 1 quả Trứng chiên + 20g Bơ đậu phộng | D7: 390 | E7: 17 | F7: 34 | G7: 20 | H7: 1 | I7: =D7/H7 | J7: =E7/H7 | K7: =F7/H7 | L7: =G7/H7 | M7: 12000 | N7: 7 phút | O7: Chiên trứng chín kẹp bánh mì phết bơ đậu phộng. Bữa sáng hoặc bữa phụ cực nhanh.
A8: RCP004 | B8: [SAMPLE] Yến Mạch Ngâm Sữa Chua & Chuối (Overnight) | C8: 50g Yến mạch + 1 hộp Sữa chua có đường + 100ml Sữa tươi + 1 quả chuối | D8: 430 | E8: 15 | F8: 73 | G8: 8 | H8: 1 | I8: =D8/H8 | J8: =E8/H8 | K8: =F8/H8 | L8: =G8/H8 | M8: 16000 | N8: 5 phút | O8: Trộn đều các nguyên liệu vào hũ thủy tinh, để tủ lạnh qua đêm. Sáng dậy mở ra ăn ngay.
A9: RCP005 | B9: [SAMPLE] Cơm Thịt Heo Nạc Xào Đậu Phụ Cà Chua | C9: 250g Cơm trắng + 100g Thịt heo nạc + 100g Đậu phụ + 1 quả cà chua + 5g Dầu ăn | D9: 610 | E9: 36 | F9: 75 | G9: 17 | H9: 1 | I9: =D9/H9 | J9: =E9/H9 | K9: =F9/H9 | L9: =G9/H9 | M9: 26000 | N9: 25 phút | O9: Xào thịt heo săn lại rồi cho sốt cà chua và đậu phụ om mềm. Vị chua ngọt dễ ăn nhiều cơm.
A10: RCP006 | B10: [SAMPLE] Cháo Thịt Bò Bằm & Trứng Gà Hành Hoa | C10: 70g Gạo nấu cháo (~300g cháo) + 80g Thịt bò bằm + 1 quả Trứng gà đánh tan + Hành hoa | D10: 520 | E10: 31 | F10: 58 | G10: 16 | H10: 1 | I10: =D10/H10 | J10: =E10/H10 | K10: =F10/H10 | L10: =G10/H10 | M10: 30000 | N10: 30 phút | O10: Nấu cháo nhừ, cho bò bằm xào thơm và trứng vào khuấy đều. Cực kỳ thích hợp khi đầy bụng, khó tiêu.

Sheet 05_WEEKLY_MEAL_PLAN
A1: KẾ HOẠCH THỰC ĐƠN TUẦN MẪU CHO SINH VIÊN (WEEKLY MEAL PLAN TEMPLATE)
A3: Tuần | B3: Thứ | C3: Thời Gian | D3: Bữa Ăn | E3: Tên Món Kế Hoạch | F3: Thành Phần Thực Phẩm | G3: Khẩu Phần | H3: Kcal Dự Kiến | I3: Protein (g) | J3: Carb (g) | K3: Fat (g) | L3: Chi Phí (VNĐ) | M3: Trạng Thái | N3: Phương Án Thay Thế
A4: 1 | B4: Thứ Hai | C4: 07:00 | D4: Bữa sáng | E4: Bánh mì kẹp trứng bơ đậu phộng + Sữa tươi | F4: 2 lát sandwich, 1 trứng, 20g bơ đậu phộng, 1 hộp sữa 220ml | G4: 1 suất | H4: 550 | I4: 23 | J4: 52 | K4: 27 | L4: 16000 | M4: Tự nấu tại phòng | N4: Thay bằng Bún bò / Phở bò quán quen
A5: 1 | B5: Thứ Hai | C5: 10:00 | D5: Bữa phụ sáng | E5: Chuối tiêu chín + Sữa chua có đường | F5: 1 quả chuối (100g) + 1 hộp sữa chua (100g) | G5: 1 suất | H5: 190 | I5: 4.3 | J5: 37 | K5: 3.1 | L5: 8000 | M5: Chuẩn bị sẵn | N5: Thay bằng 30g Đậu phộng rang
A6: 1 | B6: Thứ Hai | C6: 12:30 | D6: Bữa trưa | E6: Cơm ức gà xào nấm & Trứng ốp la | F6: 250g Cơm trắng, 150g Ức gà, 1 Trứng gà, rau cải | G6: 1 suất | H6: 680 | I6: 48 | J6: 76 | K6: 19 | L6: 32000 | M6: Meal-prep sẵn | N6: Thay bằng Cơm thịt heo luộc
A7: 1 | B7: Thứ Hai | C7: 16:30 | D7: Bữa phụ chiều | E7: Sinh Tố Mass Tự Làm (Pre-workout) | F7: Chuối + Yến mạch + Bơ đậu phộng + Sữa tươi | G7: 1 ly lớn | H7: 625 | I7: 20.5 | J7: 81 | K7: 24 | L7: 19000 | M7: Xay trước tập | N7: Uống sữa tươi + 1 bánh bao
A8: 1 | B8: Thứ Hai | C8: 19:30 | D8: Bữa tối | E8: Cơm thịt heo nạc xào đậu phụ cà chua | F8: 250g Cơm trắng, 100g Thịt nạc, 100g Đậu phụ, rau muống | G8: 1 suất | H8: 610 | I8: 36 | J8: 75 | K8: 17 | L8: 26000 | M8: Nấu tươi buổi tối | N8: Thay bằng Cá basa chiên sốt cà
A9: TỔNG CỘNG DỰ KIẾN (Thứ Hai) | H9: =SUM(H4:H8) | I9: =SUM(I4:I8) | J9: =SUM(J4:J8) | K9: =SUM(K4:K8) | L9: =SUM(L4:L8) | M9: ĐẠT MỤC TIÊU | N9: Năng lượng chuẩn ~2.650 kcal
A10: 1 | B10: Thứ Ba | C10: 07:00 | D10: Bữa sáng | E10: Bánh mì kẹp trứng bơ đậu phộng + Sữa tươi | F10: 2 lát sandwich, 1 trứng, 20g bơ đậu phộng, 1 hộp sữa 220ml | G10: 1 suất | H10: 550 | I10: 23 | J10: 52 | K10: 27 | L10: 16000 | M10: Tự nấu tại phòng | N10: Thay bằng Bún bò / Phở bò quán quen
A11: 1 | B11: Thứ Ba | C11: 10:00 | D11: Bữa phụ sáng | E11: Chuối tiêu chín + Sữa chua có đường | F11: 1 quả chuối (100g) + 1 hộp sữa chua (100g) | G11: 1 suất | H11: 190 | I11: 4.3 | J11: 37 | K11: 3.1 | L11: 8000 | M11: Chuẩn bị sẵn | N11: Thay bằng 30g Đậu phộng rang
A12: 1 | B12: Thứ Ba | C12: 12:30 | D12: Bữa trưa | E12: Cơm ức gà xào nấm & Trứng ốp la | F12: 250g Cơm trắng, 150g Ức gà, 1 Trứng gà, rau cải | G12: 1 suất | H12: 680 | I12: 48 | J12: 76 | K12: 19 | L12: 32000 | M12: Meal-prep sẵn | N12: Thay bằng Cơm thịt heo luộc
A13: 1 | B13: Thứ Ba | C13: 16:30 | D13: Bữa phụ chiều | E13: Sinh Tố Mass Tự Làm (Pre-workout) | F13: Chuối + Yến mạch + Bơ đậu phộng + Sữa tươi | G13: 1 ly lớn | H13: 625 | I13: 20.5 | J13: 81 | K13: 24 | L13: 19000 | M13: Xay trước tập | N13: Uống sữa tươi + 1 bánh bao
A14: 1 | B14: Thứ Ba | C14: 19:30 | D14: Bữa tối | E14: Cơm thịt heo nạc xào đậu phụ cà chua | F14: 250g Cơm trắng, 100g Thịt nạc, 100g Đậu phụ, rau muống | G14: 1 suất | H14: 610 | I14: 36 | J14: 75 | K14: 17 | L14: 26000 | M14: Nấu tươi buổi tối | N14: Thay bằng Cá basa chiên sốt cà
A15: TỔNG CỘNG DỰ KIẾN (Thứ Ba) | H15: =SUM(H10:H14) | I15: =SUM(I10:I14) | J15: =SUM(J10:J14) | K15: =SUM(K10:K14) | L15: =SUM(L10:L14) | M15: ĐẠT MỤC TIÊU | N15: Năng lượng chuẩn ~2.650 kcal
A16: 1 | B16: Thứ Tư | C16: 07:00 | D16: Bữa sáng | E16: Bánh mì kẹp trứng bơ đậu phộng + Sữa tươi | F16: 2 lát sandwich, 1 trứng, 20g bơ đậu phộng, 1 hộp sữa 220ml | G16: 1 suất | H16: 550 | I16: 23 | J16: 52 | K16: 27 | L16: 16000 | M16: Tự nấu tại phòng | N16: Thay bằng Bún bò / Phở bò quán quen
A17: 1 | B17: Thứ Tư | C17: 10:00 | D17: Bữa phụ sáng | E17: Chuối tiêu chín + Sữa chua có đường | F17: 1 quả chuối (100g) + 1 hộp sữa chua (100g) | G17: 1 suất | H17: 190 | I17: 4.3 | J17: 37 | K17: 3.1 | L17: 8000 | M17: Chuẩn bị sẵn | N17: Thay bằng 30g Đậu phộng rang
A18: 1 | B18: Thứ Tư | C18: 12:30 | D18: Bữa trưa | E18: Cơm ức gà xào nấm & Trứng ốp la | F18: 250g Cơm trắng, 150g Ức gà, 1 Trứng gà, rau cải | G18: 1 suất | H18: 680 | I18: 48 | J18: 76 | K18: 19 | L18: 32000 | M18: Meal-prep sẵn | N18: Thay bằng Cơm thịt heo luộc
A19: 1 | B19: Thứ Tư | C19: 16:30 | D19: Bữa phụ chiều | E19: Sinh Tố Mass Tự Làm (Pre-workout) | F19: Chuối + Yến mạch + Bơ đậu phộng + Sữa tươi | G19: 1 ly lớn | H19: 625 | I19: 20.5 | J19: 81 | K19: 24 | L19: 19000 | M19: Xay trước tập | N19: Uống sữa tươi + 1 bánh bao
A20: 1 | B20: Thứ Tư | C20: 19:30 | D20: Bữa tối | E20: Cơm thịt heo nạc xào đậu phụ cà chua | F20: 250g Cơm trắng, 100g Thịt nạc, 100g Đậu phụ, rau muống | G20: 1 suất | H20: 610 | I20: 36 | J20: 75 | K20: 17 | L20: 26000 | M20: Nấu tươi buổi tối | N20: Thay bằng Cá basa chiên sốt cà
A21: TỔNG CỘNG DỰ KIẾN (Thứ Tư) | H21: =SUM(H16:H20) | I21: =SUM(I16:I20) | J21: =SUM(J16:J20) | K21: =SUM(K16:K20) | L21: =SUM(L16:L20) | M21: ĐẠT MỤC TIÊU | N21: Năng lượng chuẩn ~2.650 kcal
A22: 1 | B22: Thứ Năm | C22: 07:00 | D22: Bữa sáng | E22: Bánh mì kẹp trứng bơ đậu phộng + Sữa tươi | F22: 2 lát sandwich, 1 trứng, 20g bơ đậu phộng, 1 hộp sữa 220ml | G22: 1 suất | H22: 550 | I22: 23 | J22: 52 | K22: 27 | L22: 16000 | M22: Tự nấu tại phòng | N22: Thay bằng Bún bò / Phở bò quán quen
A23: 1 | B23: Thứ Năm | C23: 10:00 | D23: Bữa phụ sáng | E23: Chuối tiêu chín + Sữa chua có đường | F23: 1 quả chuối (100g) + 1 hộp sữa chua (100g) | G23: 1 suất | H23: 190 | I23: 4.3 | J23: 37 | K23: 3.1 | L23: 8000 | M23: Chuẩn bị sẵn | N23: Thay bằng 30g Đậu phộng rang
A24: 1 | B24: Thứ Năm | C24: 12:30 | D24: Bữa trưa | E24: Cơm ức gà xào nấm & Trứng ốp la | F24: 250g Cơm trắng, 150g Ức gà, 1 Trứng gà, rau cải | G24: 1 suất | H24: 680 | I24: 48 | J24: 76 | K24: 19 | L24: 32000 | M24: Meal-prep sẵn | N24: Thay bằng Cơm thịt heo luộc
A25: 1 | B25: Thứ Năm | C25: 16:30 | D25: Bữa phụ chiều | E25: Sinh Tố Mass Tự Làm (Pre-workout) | F25: Chuối + Yến mạch + Bơ đậu phộng + Sữa tươi | G25: 1 ly lớn | H25: 625 | I25: 20.5 | J25: 81 | K25: 24 | L25: 19000 | M25: Xay trước tập | N25: Uống sữa tươi + 1 bánh bao
A26: 1 | B26: Thứ Năm | C26: 19:30 | D26: Bữa tối | E26: Cơm thịt heo nạc xào đậu phụ cà chua | F26: 250g Cơm trắng, 100g Thịt nạc, 100g Đậu phụ, rau muống | G26: 1 suất | H26: 610 | I26: 36 | J26: 75 | K26: 17 | L26: 26000 | M26: Nấu tươi buổi tối | N26: Thay bằng Cá basa chiên sốt cà
A27: TỔNG CỘNG DỰ KIẾN (Thứ Năm) | H27: =SUM(H22:H26) | I27: =SUM(I22:I26) | J27: =SUM(J22:J26) | K27: =SUM(K22:K26) | L27: =SUM(L22:L26) | M27: ĐẠT MỤC TIÊU | N27: Năng lượng chuẩn ~2.650 kcal
A28: 1 | B28: Thứ Sáu | C28: 07:00 | D28: Bữa sáng | E28: Bánh mì kẹp trứng bơ đậu phộng + Sữa tươi | F28: 2 lát sandwich, 1 trứng, 20g bơ đậu phộng, 1 hộp sữa 220ml | G28: 1 suất | H28: 550 | I28: 23 | J28: 52 | K28: 27 | L28: 16000 | M28: Tự nấu tại phòng | N28: Thay bằng Bún bò / Phở bò quán quen
A29: 1 | B29: Thứ Sáu | C29: 10:00 | D29: Bữa phụ sáng | E29: Chuối tiêu chín + Sữa chua có đường | F29: 1 quả chuối (100g) + 1 hộp sữa chua (100g) | G29: 1 suất | H29: 190 | I29: 4.3 | J29: 37 | K29: 3.1 | L29: 8000 | M29: Chuẩn bị sẵn | N29: Thay bằng 30g Đậu phộng rang
A30: 1 | B30: Thứ Sáu | C30: 12:30 | D30: Bữa trưa | E30: Cơm ức gà xào nấm & Trứng ốp la | F30: 250g Cơm trắng, 150g Ức gà, 1 Trứng gà, rau cải | G30: 1 suất | H30: 680 | I30: 48 | J30: 76 | K30: 19 | L30: 32000 | M30: Meal-prep sẵn | N30: Thay bằng Cơm thịt heo luộc
A31: 1 | B31: Thứ Sáu | C31: 16:30 | D31: Bữa phụ chiều | E31: Sinh Tố Mass Tự Làm (Pre-workout) | F31: Chuối + Yến mạch + Bơ đậu phộng + Sữa tươi | G31: 1 ly lớn | H31: 625 | I31: 20.5 | J31: 81 | K31: 24 | L31: 19000 | M31: Xay trước tập | N31: Uống sữa tươi + 1 bánh bao
A32: 1 | B32: Thứ Sáu | C32: 19:30 | D32: Bữa tối | E32: Cơm thịt heo nạc xào đậu phụ cà chua | F32: 250g Cơm trắng, 100g Thịt nạc, 100g Đậu phụ, rau muống | G32: 1 suất | H32: 610 | I32: 36 | J32: 75 | K32: 17 | L32: 26000 | M32: Nấu tươi buổi tối | N32: Thay bằng Cá basa chiên sốt cà
A33: TỔNG CỘNG DỰ KIẾN (Thứ Sáu) | H33: =SUM(H28:H32) | I33: =SUM(I28:I32) | J33: =SUM(J28:J32) | K33: =SUM(K28:K32) | L33: =SUM(L28:L32) | M33: ĐẠT MỤC TIÊU | N33: Năng lượng chuẩn ~2.650 kcal
A34: 1 | B34: Thứ Bảy | C34: 07:00 | D34: Bữa sáng | E34: Bánh mì kẹp trứng bơ đậu phộng + Sữa tươi | F34: 2 lát sandwich, 1 trứng, 20g bơ đậu phộng, 1 hộp sữa 220ml | G34: 1 suất | H34: 550 | I34: 23 | J34: 52 | K34: 27 | L34: 16000 | M34: Tự nấu tại phòng | N34: Thay bằng Bún bò / Phở bò quán quen
A35: 1 | B35: Thứ Bảy | C35: 10:00 | D35: Bữa phụ sáng | E35: Chuối tiêu chín + Sữa chua có đường | F35: 1 quả chuối (100g) + 1 hộp sữa chua (100g) | G35: 1 suất | H35: 190 | I35: 4.3 | J35: 37 | K35: 3.1 | L35: 8000 | M35: Chuẩn bị sẵn | N35: Thay bằng 30g Đậu phộng rang
A36: 1 | B36: Thứ Bảy | C36: 12:30 | D36: Bữa trưa | E36: Cơm ức gà xào nấm & Trứng ốp la | F36: 250g Cơm trắng, 150g Ức gà, 1 Trứng gà, rau cải | G36: 1 suất | H36: 680 | I36: 48 | J36: 76 | K36: 19 | L36: 32000 | M36: Meal-prep sẵn | N36: Thay bằng Cơm thịt heo luộc
A37: 1 | B37: Thứ Bảy | C37: 16:30 | D37: Bữa phụ chiều | E37: Sinh Tố Mass Tự Làm (Pre-workout) | F37: Chuối + Yến mạch + Bơ đậu phộng + Sữa tươi | G37: 1 ly lớn | H37: 625 | I37: 20.5 | J37: 81 | K37: 24 | L37: 19000 | M37: Xay trước tập | N37: Uống sữa tươi + 1 bánh bao
A38: 1 | B38: Thứ Bảy | C38: 19:30 | D38: Bữa tối | E38: Cơm thịt heo nạc xào đậu phụ cà chua | F38: 250g Cơm trắng, 100g Thịt nạc, 100g Đậu phụ, rau muống | G38: 1 suất | H38: 610 | I38: 36 | J38: 75 | K38: 17 | L38: 26000 | M38: Nấu tươi buổi tối | N38: Thay bằng Cá basa chiên sốt cà
A39: TỔNG CỘNG DỰ KIẾN (Thứ Bảy) | H39: =SUM(H34:H38) | I39: =SUM(I34:I38) | J39: =SUM(J34:J38) | K39: =SUM(K34:K38) | L39: =SUM(L34:L38) | M39: ĐẠT MỤC TIÊU | N39: Năng lượng chuẩn ~2.650 kcal
A40: 1 | B40: Chủ Nhật | C40: 07:00 | D40: Bữa sáng | E40: Bánh mì kẹp trứng bơ đậu phộng + Sữa tươi | F40: 2 lát sandwich, 1 trứng, 20g bơ đậu phộng, 1 hộp sữa 220ml | G40: 1 suất | H40: 550 | I40: 23 | J40: 52 | K40: 27 | L40: 16000 | M40: Tự nấu tại phòng | N40: Thay bằng Bún bò / Phở bò quán quen
A41: 1 | B41: Chủ Nhật | C41: 10:00 | D41: Bữa phụ sáng | E41: Chuối tiêu chín + Sữa chua có đường | F41: 1 quả chuối (100g) + 1 hộp sữa chua (100g) | G41: 1 suất | H41: 190 | I41: 4.3 | J41: 37 | K41: 3.1 | L41: 8000 | M41: Chuẩn bị sẵn | N41: Thay bằng 30g Đậu phộng rang
...

Sheet 06_DAILY_NUTRITION_LOG
A1: NHẬT KÝ ĂN UỐNG THỰC TẾ CHI TIẾT (MEAL LOG ENTRIES) | N1: BẢNG TỔNG HỢP THEO NGÀY (DAILY NUTRITION ROLLUP)
A2: Nhập khối lượng và tên món. Kcal, Protein, Carb, Fat được tính TỰ ĐỘNG từ Database. Chọn Mức độ tin cậy để đánh giá tính chuẩn xác. | N2: Quy tắc an toàn: Ngày CHƯA NHẬP sẽ để trống calo, KHÔNG BAO GIỜ tính là 0 calo để tránh làm lệch số liệu trung bình tuần!
A4: Ngày | B4: Bữa Ăn | C4: Món Ăn / Thực Phẩm | D4: Khối Lượng | E4: Đơn Vị | F4: Kcal | G4: Protein (g) | H4: Carb (g) | I4: Fat (g) | J4: Chi Phí | K4: Mức Độ Tin Cậy | L4: Ghi Chú | N4: Ngày Tổng Hợp | O4: Thứ | P4: Tổng Kcal | Q4: Tổng Đạm (g) | R4: Tổng Carb (g) | S4: Tổng Fat (g) | T4: Tổng Chi Phí | U4: Số Bữa | V4: Trạng Thái Ngày | W4: % Đạt Kcal | X4: % Đạt Protein
A5: 46314 | B5: Bữa sáng | C5: Bánh mì sandwich trắng | D5: 60 | E5: g | F5: =IF(OR(C5="", D5=""), "", IFERROR(VLOOKUP(C5, '03_FOOD_DATABASE'!$B$5:$L$60, 6, FALSE)*D5/100, IFERROR(VLOOKUP(C5, '04_RECIPE_DATABASE'!$B$5:$M$20, 8, FALSE)*D5, 0))) | G5: =IF(OR(C5="", D5=""), "", IFERROR(VLOOKUP(C5, '03_FOOD_DATABASE'!$B$5:$L$60, 7, FALSE)*D5/100, IFERROR(VLOOKUP(C5, '04_RECIPE_DATABASE'!$B$5:$M$20, 9, FALSE)*D5, 0))) | H5: =IF(OR(C5="", D5=""), "", IFERROR(VLOOKUP(C5, '03_FOOD_DATABASE'!$B$5:$L$60, 8, FALSE)*D5/100, IFERROR(VLOOKUP(C5, '04_RECIPE_DATABASE'!$B$5:$M$20, 10, FALSE)*D5, 0))) | I5: =IF(OR(C5="", D5=""), "", IFERROR(VLOOKUP(C5, '03_FOOD_DATABASE'!$B$5:$L$60, 9, FALSE)*D5/100, IFERROR(VLOOKUP(C5, '04_RECIPE_DATABASE'!$B$5:$M$20, 11, FALSE)*D5, 0))) | J5: =IF(OR(C5="", D5=""), "", IFERROR(VLOOKUP(C5, '03_FOOD_DATABASE'!$B$5:$L$60, 11, FALSE)*D5/100, IFERROR(VLOOKUP(C5, '04_RECIPE_DATABASE'!$B$5:$M$20, 12, FALSE)*D5, 0))) | K5: Đã cân thực tế (Cân điện tử) | L5: 2 lát sandwich | N5: 46314 | O5: =TEXT(N5, "dddd") | P5: =IF(U5=0, "", SUMIFS($F$5:$F$1500, $A$5:$A$1500, N5)) | Q5: =IF(U5=0, "", SUMIFS($G$5:$G$1500, $A$5:$A$1500, N5)) | R5: =IF(U5=0, "", SUMIFS($H$5:$H$1500, $A$5:$A$1500, N5)) | S5: =IF(U5=0, "", SUMIFS($I$5:$I$1500, $A$5:$A$1500, N5)) | T5: =IF(U5=0, "", SUMIFS($J$5:$J$1500, $A$5:$A$1500, N5)) | U5: =COUNTIFS($A$5:$A$1500, N5) | V5: =IF(U5=0, "CHƯA NHẬP", IF(U5<3, "INCOMPLETE (Chưa đủ bữa)", "COMPLETE (Đầy đủ)")) | W5: =IF(P5="", "", P5/'02_NUTRITION_SETUP'!$C$20) | X5: =IF(Q5="", "", Q5/'02_NUTRITION_SETUP'!$C$21)
A6: 46314 | B6: Bữa sáng | C6: Trứng gà công nghiệp (1 quả ~50g) | D6: 2 | E6: quả | F6: =IF(OR(C6="", D6=""), "", IFERROR(VLOOKUP(C6, '03_FOOD_DATABASE'!$B$5:$L$60, 6, FALSE)*D6/100, IFERROR(VLOOKUP(C6, '04_RECIPE_DATABASE'!$B$5:$M$20, 8, FALSE)*D6, 0))) | G6: =IF(OR(C6="", D6=""), "", IFERROR(VLOOKUP(C6, '03_FOOD_DATABASE'!$B$5:$L$60, 7, FALSE)*D6/100, IFERROR(VLOOKUP(C6, '04_RECIPE_DATABASE'!$B$5:$M$20, 9, FALSE)*D6, 0))) | H6: =IF(OR(C6="", D6=""), "", IFERROR(VLOOKUP(C6, '03_FOOD_DATABASE'!$B$5:$L$60, 8, FALSE)*D6/100, IFERROR(VLOOKUP(C6, '04_RECIPE_DATABASE'!$B$5:$M$20, 10, FALSE)*D6, 0))) | I6: =IF(OR(C6="", D6=""), "", IFERROR(VLOOKUP(C6, '03_FOOD_DATABASE'!$B$5:$L$60, 9, FALSE)*D6/100, IFERROR(VLOOKUP(C6, '04_RECIPE_DATABASE'!$B$5:$M$20, 11, FALSE)*D6, 0))) | J6: =IF(OR(C6="", D6=""), "", IFERROR(VLOOKUP(C6, '03_FOOD_DATABASE'!$B$5:$L$60, 11, FALSE)*D6/100, IFERROR(VLOOKUP(C6, '04_RECIPE_DATABASE'!$B$5:$M$20, 12, FALSE)*D6, 0))) | K6: Đã cân thực tế (Cân điện tử) | L6: 2 quả ốp la | N6: 46315 | O6: =TEXT(N6, "dddd") | P6: =IF(U6=0, "", SUMIFS($F$5:$F$1500, $A$5:$A$1500, N6)) | Q6: =IF(U6=0, "", SUMIFS($G$5:$G$1500, $A$5:$A$1500, N6)) | R6: =IF(U6=0, "", SUMIFS($H$5:$H$1500, $A$5:$A$1500, N6)) | S6: =IF(U6=0, "", SUMIFS($I$5:$I$1500, $A$5:$A$1500, N6)) | T6: =IF(U6=0, "", SUMIFS($J$5:$J$1500, $A$5:$A$1500, N6)) | U6: =COUNTIFS($A$5:$A$1500, N6) | V6: =IF(U6=0, "CHƯA NHẬP", IF(U6<3, "INCOMPLETE (Chưa đủ bữa)", "COMPLETE (Đầy đủ)")) | W6: =IF(P6="", "", P6/'02_NUTRITION_SETUP'!$C$20) | X6: =IF(Q6="", "", Q6/'02_NUTRITION_SETUP'!$C$21)
A7: 46314 | B7: Bữa sáng | C7: Bơ đậu phộng (Peanut Butter) | D7: 20 | E7: g | F7: =IF(OR(C7="", D7=""), "", IFERROR(VLOOKUP(C7, '03_FOOD_DATABASE'!$B$5:$L$60, 6, FALSE)*D7/100, IFERROR(VLOOKUP(C7, '04_RECIPE_DATABASE'!$B$5:$M$20, 8, FALSE)*D7, 0))) | G7: =IF(OR(C7="", D7=""), "", IFERROR(VLOOKUP(C7, '03_FOOD_DATABASE'!$B$5:$L$60, 7, FALSE)*D7/100, IFERROR(VLOOKUP(C7, '04_RECIPE_DATABASE'!$B$5:$M$20, 9, FALSE)*D7, 0))) | H7: =IF(OR(C7="", D7=""), "", IFERROR(VLOOKUP(C7, '03_FOOD_DATABASE'!$B$5:$L$60, 8, FALSE)*D7/100, IFERROR(VLOOKUP(C7, '04_RECIPE_DATABASE'!$B$5:$M$20, 10, FALSE)*D7, 0))) | I7: =IF(OR(C7="", D7=""), "", IFERROR(VLOOKUP(C7, '03_FOOD_DATABASE'!$B$5:$L$60, 9, FALSE)*D7/100, IFERROR(VLOOKUP(C7, '04_RECIPE_DATABASE'!$B$5:$M$20, 11, FALSE)*D7, 0))) | J7: =IF(OR(C7="", D7=""), "", IFERROR(VLOOKUP(C7, '03_FOOD_DATABASE'!$B$5:$L$60, 11, FALSE)*D7/100, IFERROR(VLOOKUP(C7, '04_RECIPE_DATABASE'!$B$5:$M$20, 12, FALSE)*D7, 0))) | K7: Đã cân thực tế (Cân điện tử) | L7: Phết bánh mì | N7: 46316 | O7: =TEXT(N7, "dddd") | P7: =IF(U7=0, "", SUMIFS($F$5:$F$1500, $A$5:$A$1500, N7)) | Q7: =IF(U7=0, "", SUMIFS($G$5:$G$1500, $A$5:$A$1500, N7)) | R7: =IF(U7=0, "", SUMIFS($H$5:$H$1500, $A$5:$A$1500, N7)) | S7: =IF(U7=0, "", SUMIFS($I$5:$I$1500, $A$5:$A$1500, N7)) | T7: =IF(U7=0, "", SUMIFS($J$5:$J$1500, $A$5:$A$1500, N7)) | U7: =COUNTIFS($A$5:$A$1500, N7) | V7: =IF(U7=0, "CHƯA NHẬP", IF(U7<3, "INCOMPLETE (Chưa đủ bữa)", "COMPLETE (Đầy đủ)")) | W7: =IF(P7="", "", P7/'02_NUTRITION_SETUP'!$C$20) | X7: =IF(Q7="", "", Q7/'02_NUTRITION_SETUP'!$C$21)
A8: 46314 | B8: Bữa sáng | C8: Sữa tươi có đường (Vinamilk) | D8: 220 | E8: ml | F8: =IF(OR(C8="", D8=""), "", IFERROR(VLOOKUP(C8, '03_FOOD_DATABASE'!$B$5:$L$60, 6, FALSE)*D8/100, IFERROR(VLOOKUP(C8, '04_RECIPE_DATABASE'!$B$5:$M$20, 8, FALSE)*D8, 0))) | G8: =IF(OR(C8="", D8=""), "", IFERROR(VLOOKUP(C8, '03_FOOD_DATABASE'!$B$5:$L$60, 7, FALSE)*D8/100, IFERROR(VLOOKUP(C8, '04_RECIPE_DATABASE'!$B$5:$M$20, 9, FALSE)*D8, 0))) | H8: =IF(OR(C8="", D8=""), "", IFERROR(VLOOKUP(C8, '03_FOOD_DATABASE'!$B$5:$L$60, 8, FALSE)*D8/100, IFERROR(VLOOKUP(C8, '04_RECIPE_DATABASE'!$B$5:$M$20, 10, FALSE)*D8, 0))) | I8: =IF(OR(C8="", D8=""), "", IFERROR(VLOOKUP(C8, '03_FOOD_DATABASE'!$B$5:$L$60, 9, FALSE)*D8/100, IFERROR(VLOOKUP(C8, '04_RECIPE_DATABASE'!$B$5:$M$20, 11, FALSE)*D8, 0))) | J8: =IF(OR(C8="", D8=""), "", IFERROR(VLOOKUP(C8, '03_FOOD_DATABASE'!$B$5:$L$60, 11, FALSE)*D8/100, IFERROR(VLOOKUP(C8, '04_RECIPE_DATABASE'!$B$5:$M$20, 12, FALSE)*D8, 0))) | K8: Đã cân thực tế (Cân điện tử) | L8: 1 hộp 220ml | N8: 46317 | O8: =TEXT(N8, "dddd") | P8: =IF(U8=0, "", SUMIFS($F$5:$F$1500, $A$5:$A$1500, N8)) | Q8: =IF(U8=0, "", SUMIFS($G$5:$G$1500, $A$5:$A$1500, N8)) | R8: =IF(U8=0, "", SUMIFS($H$5:$H$1500, $A$5:$A$1500, N8)) | S8: =IF(U8=0, "", SUMIFS($I$5:$I$1500, $A$5:$A$1500, N8)) | T8: =IF(U8=0, "", SUMIFS($J$5:$J$1500, $A$5:$A$1500, N8)) | U8: =COUNTIFS($A$5:$A$1500, N8) | V8: =IF(U8=0, "CHƯA NHẬP", IF(U8<3, "INCOMPLETE (Chưa đủ bữa)", "COMPLETE (Đầy đủ)")) | W8: =IF(P8="", "", P8/'02_NUTRITION_SETUP'!$C$20) | X8: =IF(Q8="", "", Q8/'02_NUTRITION_SETUP'!$C$21)
A9: 46314 | B9: Bữa phụ sáng | C9: Chuối tiêu chín | D9: 100 | E9: g | F9: =IF(OR(C9="", D9=""), "", IFERROR(VLOOKUP(C9, '03_FOOD_DATABASE'!$B$5:$L$60, 6, FALSE)*D9/100, IFERROR(VLOOKUP(C9, '04_RECIPE_DATABASE'!$B$5:$M$20, 8, FALSE)*D9, 0))) | G9: =IF(OR(C9="", D9=""), "", IFERROR(VLOOKUP(C9, '03_FOOD_DATABASE'!$B$5:$L$60, 7, FALSE)*D9/100, IFERROR(VLOOKUP(C9, '04_RECIPE_DATABASE'!$B$5:$M$20, 9, FALSE)*D9, 0))) | H9: =IF(OR(C9="", D9=""), "", IFERROR(VLOOKUP(C9, '03_FOOD_DATABASE'!$B$5:$L$60, 8, FALSE)*D9/100, IFERROR(VLOOKUP(C9, '04_RECIPE_DATABASE'!$B$5:$M$20, 10, FALSE)*D9, 0))) | I9: =IF(OR(C9="", D9=""), "", IFERROR(VLOOKUP(C9, '03_FOOD_DATABASE'!$B$5:$L$60, 9, FALSE)*D9/100, IFERROR(VLOOKUP(C9, '04_RECIPE_DATABASE'!$B$5:$M$20, 11, FALSE)*D9, 0))) | J9: =IF(OR(C9="", D9=""), "", IFERROR(VLOOKUP(C9, '03_FOOD_DATABASE'!$B$5:$L$60, 11, FALSE)*D9/100, IFERROR(VLOOKUP(C9, '04_RECIPE_DATABASE'!$B$5:$M$20, 12, FALSE)*D9, 0))) | K9: Ước lượng khẩu phần chuẩn | L9: 1 quả chuối vừa | N9: 46318 | O9: =TEXT(N9, "dddd") | P9: =IF(U9=0, "", SUMIFS($F$5:$F$1500, $A$5:$A$1500, N9)) | Q9: =IF(U9=0, "", SUMIFS($G$5:$G$1500, $A$5:$A$1500, N9)) | R9: =IF(U9=0, "", SUMIFS($H$5:$H$1500, $A$5:$A$1500, N9)) | S9: =IF(U9=0, "", SUMIFS($I$5:$I$1500, $A$5:$A$1500, N9)) | T9: =IF(U9=0, "", SUMIFS($J$5:$J$1500, $A$5:$A$1500, N9)) | U9: =COUNTIFS($A$5:$A$1500, N9) | V9: =IF(U9=0, "CHƯA NHẬP", IF(U9<3, "INCOMPLETE (Chưa đủ bữa)", "COMPLETE (Đầy đủ)")) | W9: =IF(P9="", "", P9/'02_NUTRITION_SETUP'!$C$20) | X9: =IF(Q9="", "", Q9/'02_NUTRITION_SETUP'!$C$21)
A10: 46314 | B10: Bữa trưa | C10: Cơm trắng (nấu chín) | D10: 250 | E10: g | F10: =IF(OR(C10="", D10=""), "", IFERROR(VLOOKUP(C10, '03_FOOD_DATABASE'!$B$5:$L$60, 6, FALSE)*D10/100, IFERROR(VLOOKUP(C10, '04_RECIPE_DATABASE'!$B$5:$M$20, 8, FALSE)*D10, 0))) | G10: =IF(OR(C10="", D10=""), "", IFERROR(VLOOKUP(C10, '03_FOOD_DATABASE'!$B$5:$L$60, 7, FALSE)*D10/100, IFERROR(VLOOKUP(C10, '04_RECIPE_DATABASE'!$B$5:$M$20, 9, FALSE)*D10, 0))) | H10: =IF(OR(C10="", D10=""), "", IFERROR(VLOOKUP(C10, '03_FOOD_DATABASE'!$B$5:$L$60, 8, FALSE)*D10/100, IFERROR(VLOOKUP(C10, '04_RECIPE_DATABASE'!$B$5:$M$20, 10, FALSE)*D10, 0))) | I10: =IF(OR(C10="", D10=""), "", IFERROR(VLOOKUP(C10, '03_FOOD_DATABASE'!$B$5:$L$60, 9, FALSE)*D10/100, IFERROR(VLOOKUP(C10, '04_RECIPE_DATABASE'!$B$5:$M$20, 11, FALSE)*D10, 0))) | J10: =IF(OR(C10="", D10=""), "", IFERROR(VLOOKUP(C10, '03_FOOD_DATABASE'!$B$5:$L$60, 11, FALSE)*D10/100, IFERROR(VLOOKUP(C10, '04_RECIPE_DATABASE'!$B$5:$M$20, 12, FALSE)*D10, 0))) | K10: Đã cân thực tế (Cân điện tử) | L10: 1 bát tô đầy | N10: 46319 | O10: =TEXT(N10, "dddd") | P10: =IF(U10=0, "", SUMIFS($F$5:$F$1500, $A$5:$A$1500, N10)) | Q10: =IF(U10=0, "", SUMIFS($G$5:$G$1500, $A$5:$A$1500, N10)) | R10: =IF(U10=0, "", SUMIFS($H$5:$H$1500, $A$5:$A$1500, N10)) | S10: =IF(U10=0, "", SUMIFS($I$5:$I$1500, $A$5:$A$1500, N10)) | T10: =IF(U10=0, "", SUMIFS($J$5:$J$1500, $A$5:$A$1500, N10)) | U10: =COUNTIFS($A$5:$A$1500, N10) | V10: =IF(U10=0, "CHƯA NHẬP", IF(U10<3, "INCOMPLETE (Chưa đủ bữa)", "COMPLETE (Đầy đủ)")) | W10: =IF(P10="", "", P10/'02_NUTRITION_SETUP'!$C$20) | X10: =IF(Q10="", "", Q10/'02_NUTRITION_SETUP'!$C$21)
A11: 46314 | B11: Bữa trưa | C11: Ức gà áp chảo / Luộc | D11: 150 | E11: g | F11: =IF(OR(C11="", D11=""), "", IFERROR(VLOOKUP(C11, '03_FOOD_DATABASE'!$B$5:$L$60, 6, FALSE)*D11/100, IFERROR(VLOOKUP(C11, '04_RECIPE_DATABASE'!$B$5:$M$20, 8, FALSE)*D11, 0))) | G11: =IF(OR(C11="", D11=""), "", IFERROR(VLOOKUP(C11, '03_FOOD_DATABASE'!$B$5:$L$60, 7, FALSE)*D11/100, IFERROR(VLOOKUP(C11, '04_RECIPE_DATABASE'!$B$5:$M$20, 9, FALSE)*D11, 0))) | H11: =IF(OR(C11="", D11=""), "", IFERROR(VLOOKUP(C11, '03_FOOD_DATABASE'!$B$5:$L$60, 8, FALSE)*D11/100, IFERROR(VLOOKUP(C11, '04_RECIPE_DATABASE'!$B$5:$M$20, 10, FALSE)*D11, 0))) | I11: =IF(OR(C11="", D11=""), "", IFERROR(VLOOKUP(C11, '03_FOOD_DATABASE'!$B$5:$L$60, 9, FALSE)*D11/100, IFERROR(VLOOKUP(C11, '04_RECIPE_DATABASE'!$B$5:$M$20, 11, FALSE)*D11, 0))) | J11: =IF(OR(C11="", D11=""), "", IFERROR(VLOOKUP(C11, '03_FOOD_DATABASE'!$B$5:$L$60, 11, FALSE)*D11/100, IFERROR(VLOOKUP(C11, '04_RECIPE_DATABASE'!$B$5:$M$20, 12, FALSE)*D11, 0))) | K11: Đã cân thực tế (Cân điện tử) | L11: Ức gà luộc xé | N11: 46320 | O11: =TEXT(N11, "dddd") | P11: =IF(U11=0, "", SUMIFS($F$5:$F$1500, $A$5:$A$1500, N11)) | Q11: =IF(U11=0, "", SUMIFS($G$5:$G$1500, $A$5:$A$1500, N11)) | R11: =IF(U11=0, "", SUMIFS($H$5:$H$1500, $A$5:$A$1500, N11)) | S11: =IF(U11=0, "", SUMIFS($I$5:$I$1500, $A$5:$A$1500, N11)) | T11: =IF(U11=0, "", SUMIFS($J$5:$J$1500, $A$5:$A$1500, N11)) | U11: =COUNTIFS($A$5:$A$1500, N11) | V11: =IF(U11=0, "CHƯA NHẬP", IF(U11<3, "INCOMPLETE (Chưa đủ bữa)", "COMPLETE (Đầy đủ)")) | W11: =IF(P11="", "", P11/'02_NUTRITION_SETUP'!$C$20) | X11: =IF(Q11="", "", Q11/'02_NUTRITION_SETUP'!$C$21)
A12: 46314 | B12: Bữa trưa | C12: Rau muống luộc | D12: 150 | E12: g | F12: =IF(OR(C12="", D12=""), "", IFERROR(VLOOKUP(C12, '03_FOOD_DATABASE'!$B$5:$L$60, 6, FALSE)*D12/100, IFERROR(VLOOKUP(C12, '04_RECIPE_DATABASE'!$B$5:$M$20, 8, FALSE)*D12, 0))) | G12: =IF(OR(C12="", D12=""), "", IFERROR(VLOOKUP(C12, '03_FOOD_DATABASE'!$B$5:$L$60, 7, FALSE)*D12/100, IFERROR(VLOOKUP(C12, '04_RECIPE_DATABASE'!$B$5:$M$20, 9, FALSE)*D12, 0))) | H12: =IF(OR(C12="", D12=""), "", IFERROR(VLOOKUP(C12, '03_FOOD_DATABASE'!$B$5:$L$60, 8, FALSE)*D12/100, IFERROR(VLOOKUP(C12, '04_RECIPE_DATABASE'!$B$5:$M$20, 10, FALSE)*D12, 0))) | I12: =IF(OR(C12="", D12=""), "", IFERROR(VLOOKUP(C12, '03_FOOD_DATABASE'!$B$5:$L$60, 9, FALSE)*D12/100, IFERROR(VLOOKUP(C12, '04_RECIPE_DATABASE'!$B$5:$M$20, 11, FALSE)*D12, 0))) | J12: =IF(OR(C12="", D12=""), "", IFERROR(VLOOKUP(C12, '03_FOOD_DATABASE'!$B$5:$L$60, 11, FALSE)*D12/100, IFERROR(VLOOKUP(C12, '04_RECIPE_DATABASE'!$B$5:$M$20, 12, FALSE)*D12, 0))) | K12: Ước lượng khẩu phần chuẩn | L12: 1 đĩa rau muống | N12: 46321 | O12: =TEXT(N12, "dddd") | P12: =IF(U12=0, "", SUMIFS($F$5:$F$1500, $A$5:$A$1500, N12)) | Q12: =IF(U12=0, "", SUMIFS($G$5:$G$1500, $A$5:$A$1500, N12)) | R12: =IF(U12=0, "", SUMIFS($H$5:$H$1500, $A$5:$A$1500, N12)) | S12: =IF(U12=0, "", SUMIFS($I$5:$I$1500, $A$5:$A$1500, N12)) | T12: =IF(U12=0, "", SUMIFS($J$5:$J$1500, $A$5:$A$1500, N12)) | U12: =COUNTIFS($A$5:$A$1500, N12) | V12: =IF(U12=0, "CHƯA NHẬP", IF(U12<3, "INCOMPLETE (Chưa đủ bữa)", "COMPLETE (Đầy đủ)")) | W12: =IF(P12="", "", P12/'02_NUTRITION_SETUP'!$C$20) | X12: =IF(Q12="", "", Q12/'02_NUTRITION_SETUP'!$C$21)
A13: 46314 | B13: Bữa phụ chiều | C13: [SAMPLE] Sinh Tố Mass Tự Làm (Home-made Shake) | D13: 1 | E13: suất | F13: =IF(OR(C13="", D13=""), "", IFERROR(VLOOKUP(C13, '03_FOOD_DATABASE'!$B$5:$L$60, 6, FALSE)*D13/100, IFERROR(VLOOKUP(C13, '04_RECIPE_DATABASE'!$B$5:$M$20, 8, FALSE)*D13, 0))) | G13: =IF(OR(C13="", D13=""), "", IFERROR(VLOOKUP(C13, '03_FOOD_DATABASE'!$B$5:$L$60, 7, FALSE)*D13/100, IFERROR(VLOOKUP(C13, '04_RECIPE_DATABASE'!$B$5:$M$20, 9, FALSE)*D13, 0))) | H13: =IF(OR(C13="", D13=""), "", IFERROR(VLOOKUP(C13, '03_FOOD_DATABASE'!$B$5:$L$60, 8, FALSE)*D13/100, IFERROR(VLOOKUP(C13, '04_RECIPE_DATABASE'!$B$5:$M$20, 10, FALSE)*D13, 0))) | I13: =IF(OR(C13="", D13=""), "", IFERROR(VLOOKUP(C13, '03_FOOD_DATABASE'!$B$5:$L$60, 9, FALSE)*D13/100, IFERROR(VLOOKUP(C13, '04_RECIPE_DATABASE'!$B$5:$M$20, 11, FALSE)*D13, 0))) | J13: =IF(OR(C13="", D13=""), "", IFERROR(VLOOKUP(C13, '03_FOOD_DATABASE'!$B$5:$L$60, 11, FALSE)*D13/100, IFERROR(VLOOKUP(C13, '04_RECIPE_DATABASE'!$B$5:$M$20, 12, FALSE)*D13, 0))) | K13: Đã cân thực tế (Cân điện tử) | L13: Xay sinh tố trước tập | N13: 46322 | O13: =TEXT(N13, "dddd") | P13: =IF(U13=0, "", SUMIFS($F$5:$F$1500, $A$5:$A$1500, N13)) | Q13: =IF(U13=0, "", SUMIFS($G$5:$G$1500, $A$5:$A$1500, N13)) | R13: =IF(U13=0, "", SUMIFS($H$5:$H$1500, $A$5:$A$1500, N13)) | S13: =IF(U13=0, "", SUMIFS($I$5:$I$1500, $A$5:$A$1500, N13)) | T13: =IF(U13=0, "", SUMIFS($J$5:$J$1500, $A$5:$A$1500, N13)) | U13: =COUNTIFS($A$5:$A$1500, N13) | V13: =IF(U13=0, "CHƯA NHẬP", IF(U13<3, "INCOMPLETE (Chưa đủ bữa)", "COMPLETE (Đầy đủ)")) | W13: =IF(P13="", "", P13/'02_NUTRITION_SETUP'!$C$20) | X13: =IF(Q13="", "", Q13/'02_NUTRITION_SETUP'!$C$21)
A14: 46314 | B14: Bữa tối | C14: Cơm trắng (nấu chín) | D14: 250 | E14: g | F14: =IF(OR(C14="", D14=""), "", IFERROR(VLOOKUP(C14, '03_FOOD_DATABASE'!$B$5:$L$60, 6, FALSE)*D14/100, IFERROR(VLOOKUP(C14, '04_RECIPE_DATABASE'!$B$5:$M$20, 8, FALSE)*D14, 0))) | G14: =IF(OR(C14="", D14=""), "", IFERROR(VLOOKUP(C14, '03_FOOD_DATABASE'!$B$5:$L$60, 7, FALSE)*D14/100, IFERROR(VLOOKUP(C14, '04_RECIPE_DATABASE'!$B$5:$M$20, 9, FALSE)*D14, 0))) | H14: =IF(OR(C14="", D14=""), "", IFERROR(VLOOKUP(C14, '03_FOOD_DATABASE'!$B$5:$L$60, 8, FALSE)*D14/100, IFERROR(VLOOKUP(C14, '04_RECIPE_DATABASE'!$B$5:$M$20, 10, FALSE)*D14, 0))) | I14: =IF(OR(C14="", D14=""), "", IFERROR(VLOOKUP(C14, '03_FOOD_DATABASE'!$B$5:$L$60, 9, FALSE)*D14/100, IFERROR(VLOOKUP(C14, '04_RECIPE_DATABASE'!$B$5:$M$20, 11, FALSE)*D14, 0))) | J14: =IF(OR(C14="", D14=""), "", IFERROR(VLOOKUP(C14, '03_FOOD_DATABASE'!$B$5:$L$60, 11, FALSE)*D14/100, IFERROR(VLOOKUP(C14, '04_RECIPE_DATABASE'!$B$5:$M$20, 12, FALSE)*D14, 0))) | K14: Đã cân thực tế (Cân điện tử) | L14: Cơm nóng | N14: 46323 | O14: =TEXT(N14, "dddd") | P14: =IF(U14=0, "", SUMIFS($F$5:$F$1500, $A$5:$A$1500, N14)) | Q14: =IF(U14=0, "", SUMIFS($G$5:$G$1500, $A$5:$A$1500, N14)) | R14: =IF(U14=0, "", SUMIFS($H$5:$H$1500, $A$5:$A$1500, N14)) | S14: =IF(U14=0, "", SUMIFS($I$5:$I$1500, $A$5:$A$1500, N14)) | T14: =IF(U14=0, "", SUMIFS($J$5:$J$1500, $A$5:$A$1500, N14)) | U14: =COUNTIFS($A$5:$A$1500, N14) | V14: =IF(U14=0, "CHƯA NHẬP", IF(U14<3, "INCOMPLETE (Chưa đủ bữa)", "COMPLETE (Đầy đủ)")) | W14: =IF(P14="", "", P14/'02_NUTRITION_SETUP'!$C$20) | X14: =IF(Q14="", "", Q14/'02_NUTRITION_SETUP'!$C$21)
A15: 46314 | B15: Bữa tối | C15: Thịt heo nạc luộc | D15: 120 | E15: g | F15: =IF(OR(C15="", D15=""), "", IFERROR(VLOOKUP(C15, '03_FOOD_DATABASE'!$B$5:$L$60, 6, FALSE)*D15/100, IFERROR(VLOOKUP(C15, '04_RECIPE_DATABASE'!$B$5:$M$20, 8, FALSE)*D15, 0))) | G15: =IF(OR(C15="", D15=""), "", IFERROR(VLOOKUP(C15, '03_FOOD_DATABASE'!$B$5:$L$60, 7, FALSE)*D15/100, IFERROR(VLOOKUP(C15, '04_RECIPE_DATABASE'!$B$5:$M$20, 9, FALSE)*D15, 0))) | H15: =IF(OR(C15="", D15=""), "", IFERROR(VLOOKUP(C15, '03_FOOD_DATABASE'!$B$5:$L$60, 8, FALSE)*D15/100, IFERROR(VLOOKUP(C15, '04_RECIPE_DATABASE'!$B$5:$M$20, 10, FALSE)*D15, 0))) | I15: =IF(OR(C15="", D15=""), "", IFERROR(VLOOKUP(C15, '03_FOOD_DATABASE'!$B$5:$L$60, 9, FALSE)*D15/100, IFERROR(VLOOKUP(C15, '04_RECIPE_DATABASE'!$B$5:$M$20, 11, FALSE)*D15, 0))) | J15: =IF(OR(C15="", D15=""), "", IFERROR(VLOOKUP(C15, '03_FOOD_DATABASE'!$B$5:$L$60, 11, FALSE)*D15/100, IFERROR(VLOOKUP(C15, '04_RECIPE_DATABASE'!$B$5:$M$20, 12, FALSE)*D15, 0))) | K15: Đã cân thực tế (Cân điện tử) | L15: Thịt nạc thăn | N15: 46324 | O15: =TEXT(N15, "dddd") | P15: =IF(U15=0, "", SUMIFS($F$5:$F$1500, $A$5:$A$1500, N15)) | Q15: =IF(U15=0, "", SUMIFS($G$5:$G$1500, $A$5:$A$1500, N15)) | R15: =IF(U15=0, "", SUMIFS($H$5:$H$1500, $A$5:$A$1500, N15)) | S15: =IF(U15=0, "", SUMIFS($I$5:$I$1500, $A$5:$A$1500, N15)) | T15: =IF(U15=0, "", SUMIFS($J$5:$J$1500, $A$5:$A$1500, N15)) | U15: =COUNTIFS($A$5:$A$1500, N15) | V15: =IF(U15=0, "CHƯA NHẬP", IF(U15<3, "INCOMPLETE (Chưa đủ bữa)", "COMPLETE (Đầy đủ)")) | W15: =IF(P15="", "", P15/'02_NUTRITION_SETUP'!$C$20) | X15: =IF(Q15="", "", Q15/'02_NUTRITION_SETUP'!$C$21)
A16: 46314 | B16: Bữa tối | C16: Đậu phụ trắng (Tofu) | D16: 100 | E16: g | F16: =IF(OR(C16="", D16=""), "", IFERROR(VLOOKUP(C16, '03_FOOD_DATABASE'!$B$5:$L$60, 6, FALSE)*D16/100, IFERROR(VLOOKUP(C16, '04_RECIPE_DATABASE'!$B$5:$M$20, 8, FALSE)*D16, 0))) | G16: =IF(OR(C16="", D16=""), "", IFERROR(VLOOKUP(C16, '03_FOOD_DATABASE'!$B$5:$L$60, 7, FALSE)*D16/100, IFERROR(VLOOKUP(C16, '04_RECIPE_DATABASE'!$B$5:$M$20, 9, FALSE)*D16, 0))) | H16: =IF(OR(C16="", D16=""), "", IFERROR(VLOOKUP(C16, '03_FOOD_DATABASE'!$B$5:$L$60, 8, FALSE)*D16/100, IFERROR(VLOOKUP(C16, '04_RECIPE_DATABASE'!$B$5:$M$20, 10, FALSE)*D16, 0))) | I16: =IF(OR(C16="", D16=""), "", IFERROR(VLOOKUP(C16, '03_FOOD_DATABASE'!$B$5:$L$60, 9, FALSE)*D16/100, IFERROR(VLOOKUP(C16, '04_RECIPE_DATABASE'!$B$5:$M$20, 11, FALSE)*D16, 0))) | J16: =IF(OR(C16="", D16=""), "", IFERROR(VLOOKUP(C16, '03_FOOD_DATABASE'!$B$5:$L$60, 11, FALSE)*D16/100, IFERROR(VLOOKUP(C16, '04_RECIPE_DATABASE'!$B$5:$M$20, 12, FALSE)*D16, 0))) | K16: Đã cân thực tế (Cân điện tử) | L16: 1 bìa đậu phụ nhỏ | N16: 46325 | O16: =TEXT(N16, "dddd") | P16: =IF(U16=0, "", SUMIFS($F$5:$F$1500, $A$5:$A$1500, N16)) | Q16: =IF(U16=0, "", SUMIFS($G$5:$G$1500, $A$5:$A$1500, N16)) | R16: =IF(U16=0, "", SUMIFS($H$5:$H$1500, $A$5:$A$1500, N16)) | S16: =IF(U16=0, "", SUMIFS($I$5:$I$1500, $A$5:$A$1500, N16)) | T16: =IF(U16=0, "", SUMIFS($J$5:$J$1500, $A$5:$A$1500, N16)) | U16: =COUNTIFS($A$5:$A$1500, N16) | V16: =IF(U16=0, "CHƯA NHẬP", IF(U16<3, "INCOMPLETE (Chưa đủ bữa)", "COMPLETE (Đầy đủ)")) | W16: =IF(P16="", "", P16/'02_NUTRITION_SETUP'!$C$20) | X16: =IF(Q16="", "", Q16/'02_NUTRITION_SETUP'!$C$21)
F17: =IF(OR(C17="", D17=""), "", IFERROR(VLOOKUP(C17, '03_FOOD_DATABASE'!$B$5:$L$60, 6, FALSE)*D17/100, IFERROR(VLOOKUP(C17, '04_RECIPE_DATABASE'!$B$5:$M$20, 8, FALSE)*D17, 0))) | G17: =IF(OR(C17="", D17=""), "", IFERROR(VLOOKUP(C17, '03_FOOD_DATABASE'!$B$5:$L$60, 7, FALSE)*D17/100, IFERROR(VLOOKUP(C17, '04_RECIPE_DATABASE'!$B$5:$M$20, 9, FALSE)*D17, 0))) | H17: =IF(OR(C17="", D17=""), "", IFERROR(VLOOKUP(C17, '03_FOOD_DATABASE'!$B$5:$L$60, 8, FALSE)*D17/100, IFERROR(VLOOKUP(C17, '04_RECIPE_DATABASE'!$B$5:$M$20, 10, FALSE)*D17, 0))) | I17: =IF(OR(C17="", D17=""), "", IFERROR(VLOOKUP(C17, '03_FOOD_DATABASE'!$B$5:$L$60, 9, FALSE)*D17/100, IFERROR(VLOOKUP(C17, '04_RECIPE_DATABASE'!$B$5:$M$20, 11, FALSE)*D17, 0))) | J17: =IF(OR(C17="", D17=""), "", IFERROR(VLOOKUP(C17, '03_FOOD_DATABASE'!$B$5:$L$60, 11, FALSE)*D17/100, IFERROR(VLOOKUP(C17, '04_RECIPE_DATABASE'!$B$5:$M$20, 12, FALSE)*D17, 0))) | N17: 46326 | O17: =TEXT(N17, "dddd") | P17: =IF(U17=0, "", SUMIFS($F$5:$F$1500, $A$5:$A$1500, N17)) | Q17: =IF(U17=0, "", SUMIFS($G$5:$G$1500, $A$5:$A$1500, N17)) | R17: =IF(U17=0, "", SUMIFS($H$5:$H$1500, $A$5:$A$1500, N17)) | S17: =IF(U17=0, "", SUMIFS($I$5:$I$1500, $A$5:$A$1500, N17)) | T17: =IF(U17=0, "", SUMIFS($J$5:$J$1500, $A$5:$A$1500, N17)) | U17: =COUNTIFS($A$5:$A$1500, N17) | V17: =IF(U17=0, "CHƯA NHẬP", IF(U17<3, "INCOMPLETE (Chưa đủ bữa)", "COMPLETE (Đầy đủ)")) | W17: =IF(P17="", "", P17/'02_NUTRITION_SETUP'!$C$20) | X17: =IF(Q17="", "", Q17/'02_NUTRITION_SETUP'!$C$21)
F18: =IF(OR(C18="", D18=""), "", IFERROR(VLOOKUP(C18, '03_FOOD_DATABASE'!$B$5:$L$60, 6, FALSE)*D18/100, IFERROR(VLOOKUP(C18, '04_RECIPE_DATABASE'!$B$5:$M$20, 8, FALSE)*D18, 0))) | G18: =IF(OR(C18="", D18=""), "", IFERROR(VLOOKUP(C18, '03_FOOD_DATABASE'!$B$5:$L$60, 7, FALSE)*D18/100, IFERROR(VLOOKUP(C18, '04_RECIPE_DATABASE'!$B$5:$M$20, 9, FALSE)*D18, 0))) | H18: =IF(OR(C18="", D18=""), "", IFERROR(VLOOKUP(C18, '03_FOOD_DATABASE'!$B$5:$L$60, 8, FALSE)*D18/100, IFERROR(VLOOKUP(C18, '04_RECIPE_DATABASE'!$B$5:$M$20, 10, FALSE)*D18, 0))) | I18: =IF(OR(C18="", D18=""), "", IFERROR(VLOOKUP(C18, '03_FOOD_DATABASE'!$B$5:$L$60, 9, FALSE)*D18/100, IFERROR(VLOOKUP(C18, '04_RECIPE_DATABASE'!$B$5:$M$20, 11, FALSE)*D18, 0))) | J18: =IF(OR(C18="", D18=""), "", IFERROR(VLOOKUP(C18, '03_FOOD_DATABASE'!$B$5:$L$60, 11, FALSE)*D18/100, IFERROR(VLOOKUP(C18, '04_RECIPE_DATABASE'!$B$5:$M$20, 12, FALSE)*D18, 0))) | N18: 46327 | O18: =TEXT(N18, "dddd") | P18: =IF(U18=0, "", SUMIFS($F$5:$F$1500, $A$5:$A$1500, N18)) | Q18: =IF(U18=0, "", SUMIFS($G$5:$G$1500, $A$5:$A$1500, N18)) | R18: =IF(U18=0, "", SUMIFS($H$5:$H$1500, $A$5:$A$1500, N18)) | S18: =IF(U18=0, "", SUMIFS($I$5:$I$1500, $A$5:$A$1500, N18)) | T18: =IF(U18=0, "", SUMIFS($J$5:$J$1500, $A$5:$A$1500, N18)) | U18: =COUNTIFS($A$5:$A$1500, N18) | V18: =IF(U18=0, "CHƯA NHẬP", IF(U18<3, "INCOMPLETE (Chưa đủ bữa)", "COMPLETE (Đầy đủ)")) | W18: =IF(P18="", "", P18/'02_NUTRITION_SETUP'!$C$20) | X18: =IF(Q18="", "", Q18/'02_NUTRITION_SETUP'!$C$21)
F19: =IF(OR(C19="", D19=""), "", IFERROR(VLOOKUP(C19, '03_FOOD_DATABASE'!$B$5:$L$60, 6, FALSE)*D19/100, IFERROR(VLOOKUP(C19, '04_RECIPE_DATABASE'!$B$5:$M$20, 8, FALSE)*D19, 0))) | G19: =IF(OR(C19="", D19=""), "", IFERROR(VLOOKUP(C19, '03_FOOD_DATABASE'!$B$5:$L$60, 7, FALSE)*D19/100, IFERROR(VLOOKUP(C19, '04_RECIPE_DATABASE'!$B$5:$M$20, 9, FALSE)*D19, 0))) | H19: =IF(OR(C19="", D19=""), "", IFERROR(VLOOKUP(C19, '03_FOOD_DATABASE'!$B$5:$L$60, 8, FALSE)*D19/100, IFERROR(VLOOKUP(C19, '04_RECIPE_DATABASE'!$B$5:$M$20, 10, FALSE)*D19, 0))) | I19: =IF(OR(C19="", D19=""), "", IFERROR(VLOOKUP(C19, '03_FOOD_DATABASE'!$B$5:$L$60, 9, FALSE)*D19/100, IFERROR(VLOOKUP(C19, '04_RECIPE_DATABASE'!$B$5:$M$20, 11, FALSE)*D19, 0))) | J19: =IF(OR(C19="", D19=""), "", IFERROR(VLOOKUP(C19, '03_FOOD_DATABASE'!$B$5:$L$60, 11, FALSE)*D19/100, IFERROR(VLOOKUP(C19, '04_RECIPE_DATABASE'!$B$5:$M$20, 12, FALSE)*D19, 0))) | N19: 46328 | O19: =TEXT(N19, "dddd") | P19: =IF(U19=0, "", SUMIFS($F$5:$F$1500, $A$5:$A$1500, N19)) | Q19: =IF(U19=0, "", SUMIFS($G$5:$G$1500, $A$5:$A$1500, N19)) | R19: =IF(U19=0, "", SUMIFS($H$5:$H$1500, $A$5:$A$1500, N19)) | S19: =IF(U19=0, "", SUMIFS($I$5:$I$1500, $A$5:$A$1500, N19)) | T19: =IF(U19=0, "", SUMIFS($J$5:$J$1500, $A$5:$A$1500, N19)) | U19: =COUNTIFS($A$5:$A$1500, N19) | V19: =IF(U19=0, "CHƯA NHẬP", IF(U19<3, "INCOMPLETE (Chưa đủ bữa)", "COMPLETE (Đầy đủ)")) | W19: =IF(P19="", "", P19/'02_NUTRITION_SETUP'!$C$20) | X19: =IF(Q19="", "", Q19/'02_NUTRITION_SETUP'!$C$21)
F20: =IF(OR(C20="", D20=""), "", IFERROR(VLOOKUP(C20, '03_FOOD_DATABASE'!$B$5:$L$60, 6, FALSE)*D20/100, IFERROR(VLOOKUP(C20, '04_RECIPE_DATABASE'!$B$5:$M$20, 8, FALSE)*D20, 0))) | G20: =IF(OR(C20="", D20=""), "", IFERROR(VLOOKUP(C20, '03_FOOD_DATABASE'!$B$5:$L$60, 7, FALSE)*D20/100, IFERROR(VLOOKUP(C20, '04_RECIPE_DATABASE'!$B$5:$M$20, 9, FALSE)*D20, 0))) | H20: =IF(OR(C20="", D20=""), "", IFERROR(VLOOKUP(C20, '03_FOOD_DATABASE'!$B$5:$L$60, 8, FALSE)*D20/100, IFERROR(VLOOKUP(C20, '04_RECIPE_DATABASE'!$B$5:$M$20, 10, FALSE)*D20, 0))) | I20: =IF(OR(C20="", D20=""), "", IFERROR(VLOOKUP(C20, '03_FOOD_DATABASE'!$B$5:$L$60, 9, FALSE)*D20/100, IFERROR(VLOOKUP(C20, '04_RECIPE_DATABASE'!$B$5:$M$20, 11, FALSE)*D20, 0))) | J20: =IF(OR(C20="", D20=""), "", IFERROR(VLOOKUP(C20, '03_FOOD_DATABASE'!$B$5:$L$60, 11, FALSE)*D20/100, IFERROR(VLOOKUP(C20, '04_RECIPE_DATABASE'!$B$5:$M$20, 12, FALSE)*D20, 0))) | N20: 46329 | O20: =TEXT(N20, "dddd") | P20: =IF(U20=0, "", SUMIFS($F$5:$F$1500, $A$5:$A$1500, N20)) | Q20: =IF(U20=0, "", SUMIFS($G$5:$G$1500, $A$5:$A$1500, N20)) | R20: =IF(U20=0, "", SUMIFS($H$5:$H$1500, $A$5:$A$1500, N20)) | S20: =IF(U20=0, "", SUMIFS($I$5:$I$1500, $A$5:$A$1500, N20)) | T20: =IF(U20=0, "", SUMIFS($J$5:$J$1500, $A$5:$A$1500, N20)) | U20: =COUNTIFS($A$5:$A$1500, N20) | V20: =IF(U20=0, "CHƯA NHẬP", IF(U20<3, "INCOMPLETE (Chưa đủ bữa)", "COMPLETE (Đầy đủ)")) | W20: =IF(P20="", "", P20/'02_NUTRITION_SETUP'!$C$20) | X20: =IF(Q20="", "", Q20/'02_NUTRITION_SETUP'!$C$21)
F21: =IF(OR(C21="", D21=""), "", IFERROR(VLOOKUP(C21, '03_FOOD_DATABASE'!$B$5:$L$60, 6, FALSE)*D21/100, IFERROR(VLOOKUP(C21, '04_RECIPE_DATABASE'!$B$5:$M$20, 8, FALSE)*D21, 0))) | G21: =IF(OR(C21="", D21=""), "", IFERROR(VLOOKUP(C21, '03_FOOD_DATABASE'!$B$5:$L$60, 7, FALSE)*D21/100, IFERROR(VLOOKUP(C21, '04_RECIPE_DATABASE'!$B$5:$M$20, 9, FALSE)*D21, 0))) | H21: =IF(OR(C21="", D21=""), "", IFERROR(VLOOKUP(C21, '03_FOOD_DATABASE'!$B$5:$L$60, 8, FALSE)*D21/100, IFERROR(VLOOKUP(C21, '04_RECIPE_DATABASE'!$B$5:$M$20, 10, FALSE)*D21, 0))) | I21: =IF(OR(C21="", D21=""), "", IFERROR(VLOOKUP(C21, '03_FOOD_DATABASE'!$B$5:$L$60, 9, FALSE)*D21/100, IFERROR(VLOOKUP(C21, '04_RECIPE_DATABASE'!$B$5:$M$20, 11, FALSE)*D21, 0))) | J21: =IF(OR(C21="", D21=""), "", IFERROR(VLOOKUP(C21, '03_FOOD_DATABASE'!$B$5:$L$60, 11, FALSE)*D21/100, IFERROR(VLOOKUP(C21, '04_RECIPE_DATABASE'!$B$5:$M$20, 12, FALSE)*D21, 0))) | N21: 46330 | O21: =TEXT(N21, "dddd") | P21: =IF(U21=0, "", SUMIFS($F$5:$F$1500, $A$5:$A$1500, N21)) | Q21: =IF(U21=0, "", SUMIFS($G$5:$G$1500, $A$5:$A$1500, N21)) | R21: =IF(U21=0, "", SUMIFS($H$5:$H$1500, $A$5:$A$1500, N21)) | S21: =IF(U21=0, "", SUMIFS($I$5:$I$1500, $A$5:$A$1500, N21)) | T21: =IF(U21=0, "", SUMIFS($J$5:$J$1500, $A$5:$A$1500, N21)) | U21: =COUNTIFS($A$5:$A$1500, N21) | V21: =IF(U21=0, "CHƯA NHẬP", IF(U21<3, "INCOMPLETE (Chưa đủ bữa)", "COMPLETE (Đầy đủ)")) | W21: =IF(P21="", "", P21/'02_NUTRITION_SETUP'!$C$20) | X21: =IF(Q21="", "", Q21/'02_NUTRITION_SETUP'!$C$21)
F22: =IF(OR(C22="", D22=""), "", IFERROR(VLOOKUP(C22, '03_FOOD_DATABASE'!$B$5:$L$60, 6, FALSE)*D22/100, IFERROR(VLOOKUP(C22, '04_RECIPE_DATABASE'!$B$5:$M$20, 8, FALSE)*D22, 0))) | G22: =IF(OR(C22="", D22=""), "", IFERROR(VLOOKUP(C22, '03_FOOD_DATABASE'!$B$5:$L$60, 7, FALSE)*D22/100, IFERROR(VLOOKUP(C22, '04_RECIPE_DATABASE'!$B$5:$M$20, 9, FALSE)*D22, 0))) | H22: =IF(OR(C22="", D22=""), "", IFERROR(VLOOKUP(C22, '03_FOOD_DATABASE'!$B$5:$L$60, 8, FALSE)*D22/100, IFERROR(VLOOKUP(C22, '04_RECIPE_DATABASE'!$B$5:$M$20, 10, FALSE)*D22, 0))) | I22: =IF(OR(C22="", D22=""), "", IFERROR(VLOOKUP(C22, '03_FOOD_DATABASE'!$B$5:$L$60, 9, FALSE)*D22/100, IFERROR(VLOOKUP(C22, '04_RECIPE_DATABASE'!$B$5:$M$20, 11, FALSE)*D22, 0))) | J22: =IF(OR(C22="", D22=""), "", IFERROR(VLOOKUP(C22, '03_FOOD_DATABASE'!$B$5:$L$60, 11, FALSE)*D22/100, IFERROR(VLOOKUP(C22, '04_RECIPE_DATABASE'!$B$5:$M$20, 12, FALSE)*D22, 0))) | N22: 46331 | O22: =TEXT(N22, "dddd") | P22: =IF(U22=0, "", SUMIFS($F$5:$F$1500, $A$5:$A$1500, N22)) | Q22: =IF(U22=0, "", SUMIFS($G$5:$G$1500, $A$5:$A$1500, N22)) | R22: =IF(U22=0, "", SUMIFS($H$5:$H$1500, $A$5:$A$1500, N22)) | S22: =IF(U22=0, "", SUMIFS($I$5:$I$1500, $A$5:$A$1500, N22)) | T22: =IF(U22=0, "", SUMIFS($J$5:$J$1500, $A$5:$A$1500, N22)) | U22: =COUNTIFS($A$5:$A$1500, N22) | V22: =IF(U22=0, "CHƯA NHẬP", IF(U22<3, "INCOMPLETE (Chưa đủ bữa)", "COMPLETE (Đầy đủ)")) | W22: =IF(P22="", "", P22/'02_NUTRITION_SETUP'!$C$20) | X22: =IF(Q22="", "", Q22/'02_NUTRITION_SETUP'!$C$21)
